File: Specimen_RawData_2.csv
Break (Cursor) : Flexure stress at Break (Cursor),"769.11438",MPa
Modulus (Automatic Young's) : Modulus (Automatic Young's),"31220.30931",MPa
Specimen properties : Support span,"125.00000",mm
Specimen properties : Thickness,"4.11000",mm
Specimen properties : Width,"12.86000",mm
Specimen properties : Specimen label,"2A"

Time,Extension,Load,Flexure stress,Flexure strain (Extension)
(s),(mm),(N),(MPa),(mm/mm)
"0.00000","0.21834","10.02791","8.65540","0.00034"
"0.40000","0.24990","11.61626","10.02636","0.00039"
"0.80000","0.28327","13.56564","11.70892","0.00045"
"1.20000","0.31656","15.53038","13.40475","0.00050"
"1.60000","0.34989","17.43122","15.04543","0.00055"
"2.00000","0.38318","19.38926","16.73547","0.00060"
"2.40000","0.41657","21.32785","18.40872","0.00066"
"2.80000","0.44984","23.32526","20.13275","0.00071"
"3.20000","0.48325","25.08601","21.65251","0.00076"
"3.60000","0.51648","27.09443","23.38604","0.00082"
"4.00000","0.54995","28.84586","24.89775","0.00087"
"4.40000","0.58315","30.68143","26.48209","0.00092"
"4.80000","0.61653","32.83550","28.34133","0.00097"
"5.20000","0.64983","34.71000","29.95927","0.00103"
"5.60000","0.68320","36.45285","31.46358","0.00108"
"6.00000","0.71654","38.12966","32.91088","0.00113"
"6.40000","0.74982","40.49155","34.94951","0.00118"
"6.80000","0.78324","42.06971","36.31167","0.00124"
"7.20000","0.81644","44.23763","38.18287","0.00129"
"7.60000","0.84993","46.35617","40.01144","0.00134"
"8.00000","0.88313","47.96115","41.39675","0.00139"
"8.40000","0.91658","49.72461","42.91885","0.00145"
"8.80000","0.94984","51.93401","44.82585","0.00150"
"9.20000","0.98317","53.56563","46.23415","0.00155"
"9.60000","1.01649","55.74826","48.11805","0.00160"
"10.00000","1.04987","57.53094","49.65673","0.00166"
"10.40000","1.08319","59.30341","51.18660","0.00171"
"10.80000","1.11653","61.50105","53.08345","0.00176"
"11.20000","1.14988","63.38370","54.70843","0.00181"
"11.60000","1.18317","65.09491","56.18543","0.00187"
"12.00000","1.21654","67.22916","58.02757","0.00192"
"12.40000","1.24980","69.28992","59.80627","0.00197"
"12.80000","1.28326","70.95994","61.24771","0.00203"
"13.20000","1.31648","73.01038","63.01752","0.00208"
"13.60000","1.34995","74.79052","64.55401","0.00213"
"14.00000","1.38316","76.55852","66.08002","0.00218"
"14.40000","1.41656","78.76575","67.98516","0.00224"
"14.80000","1.44990","80.62011","69.58571","0.00229"
"15.20000","1.48315","82.59409","71.28951","0.00234"
"15.60000","1.51659","84.33308","72.79049","0.00239"
"16.00000","1.54986","86.50266","74.66312","0.00245"
"16.40000","1.58324","88.33405","76.24384","0.00250"
"16.80000","1.61651","90.28674","77.92928","0.00255"
"17.20000","1.64993","92.27930","79.64912","0.00260"
"17.60000","1.68318","94.07688","81.20067","0.00266"
"18.00000","1.71662","95.83362","82.71696","0.00271"
"18.40000","1.74989","97.90585","84.50557","0.00276"
"18.80000","1.78320","99.71619","86.06813","0.00281"
"19.20000","1.81654","101.62513","87.71579","0.00287"
"19.60000","1.84991","103.33778","89.19403","0.00292"
"20.00000","1.88323","105.40129","90.97511","0.00297"
"20.40000","1.91658","107.51864","92.80266","0.00302"
"20.80000","1.94990","109.09977","94.16738","0.00308"
"21.20000","1.98324","111.26749","96.03841","0.00313"
"21.60000","2.01654","113.36235","97.84655","0.00318"
"22.00000","2.04988","115.10411","99.34991","0.00324"
"22.40000","2.08321","116.57405","100.61867","0.00329"
"22.80000","2.11654","118.63385","102.39655","0.00334"
"23.20000","2.14998","120.46583","103.97778","0.00339"
"23.60000","2.18316","122.53417","105.76303","0.00345"
"24.00000","2.21657","124.67557","107.61134","0.00350"
"24.40000","2.24988","126.02892","108.77946","0.00355"
"24.80000","2.28320","128.26535","110.70979","0.00360"
"25.20000","2.31657","130.13542","112.32391","0.00366"
"25.60000","2.34985","131.80717","113.76685","0.00371"
"26.00000","2.38323","133.78140","115.47086","0.00376"
"26.40000","2.41650","135.55005","116.99744","0.00381"
"26.80000","2.44988","137.36050","118.56010","0.00387"
"27.20000","2.48316","139.35849","120.28462","0.00392"
"27.60000","2.51657","141.47948","122.11531","0.00397"
"28.00000","2.54984","143.23164","123.62766","0.00402"
"28.40000","2.58322","145.06409","125.20930","0.00408"
"28.80000","2.61650","147.07585","126.94572","0.00413"
"29.20000","2.64989","148.96568","128.57689","0.00418"
"29.60000","2.68314","150.67363","130.05107","0.00423"
"30.00000","2.71656","152.32872","131.47963","0.00429"
"30.40000","2.74985","154.22060","133.11256","0.00434"
"30.80000","2.78319","156.34511","134.94630","0.00439"
"31.20000","2.81651","157.91623","136.30238","0.00445"
"31.60000","2.84983","160.06010","138.15283","0.00450"
"32.00000","2.88321","161.80511","139.65900","0.00455"
"32.40000","2.91653","163.66362","141.26314","0.00460"
"32.80000","2.94990","165.57242","142.91068","0.00466"
"33.20000","2.98313","167.42290","144.50787","0.00471"
"33.60000","3.01655","169.63052","146.41335","0.00476"
"34.00000","3.04980","170.91949","147.52589","0.00481"
"34.40000","3.08323","173.02043","149.33928","0.00487"
"34.80000","3.11650","174.73990","150.82341","0.00492"
"35.20000","3.14990","176.67342","152.49229","0.00497"
"35.60000","3.18319","178.63231","154.18307","0.00502"
"36.00000","3.21651","180.26617","155.59331","0.00508"
"36.40000","3.24988","182.74789","157.73535","0.00513"
"36.80000","3.28317","183.92570","158.75197","0.00518"
"37.20000","3.31661","186.25037","160.75845","0.00523"
"37.60000","3.34987","187.98177","162.25287","0.00529"
"38.00000","3.38322","189.99335","163.98914","0.00534"
"38.40000","3.41653","191.62529","165.39771","0.00539"
"38.80000","3.44988","193.27060","166.81783","0.00544"
"39.20000","3.48319","195.51067","168.75130","0.00550"
"39.60000","3.51659","197.13588","170.15407","0.00555"
"40.00000","3.54988","198.76973","171.56430","0.00560"
"40.40000","3.58324","200.47755","173.03838","0.00566"
"40.80000","3.61654","202.63220","174.89812","0.00571"
"41.20000","3.64986","204.22258","176.27083","0.00576"
"41.60000","3.68324","206.61069","178.33208","0.00581"
"42.00000","3.71652","208.17810","179.68495","0.00587"
"42.40000","3.74999","209.48669","180.81444","0.00592"
"42.80000","3.78316","211.53253","182.58026","0.00597"
"43.20000","3.81666","213.16360","183.98810","0.00602"
"43.60000","3.84979","215.47633","185.98428","0.00608"
"44.00000","3.88329","216.99155","187.29211","0.00613"
"44.40000","3.91656","219.03777","189.05827","0.00618"
"44.80000","3.94992","220.61665","190.42105","0.00623"
"45.20000","3.98323","222.59171","192.12578","0.00629"
"45.60000","4.01653","224.37268","193.66299","0.00634"
"46.00000","4.04989","226.40099","195.41370","0.00639"
"46.40000","4.08320","227.66772","196.50705","0.00644"
"46.80000","4.11656","229.57965","198.15729","0.00650"
"47.20000","4.14987","231.68002","199.97018","0.00655"
"47.60000","4.18326","233.08459","201.18253","0.00660"
"48.00000","4.21653","235.32893","203.11967","0.00665"
"48.40000","4.24989","236.90779","204.48244","0.00671"
"48.80000","4.28315","238.63188","205.97055","0.00676"
"49.20000","4.31658","240.61259","207.68018","0.00681"
"49.60000","4.34987","242.37111","209.19800","0.00687"
"50.00000","4.38323","244.09883","210.68925","0.00692"
"50.40000","4.41653","245.90930","212.25192","0.00697"
"50.80000","4.44983","247.45003","213.58177","0.00702"
"51.20000","4.48322","249.20923","215.10019","0.00708"
"51.60000","4.51652","251.15794","216.78218","0.00713"
"52.00000","4.54989","253.05632","218.42073","0.00718"
"52.40000","4.58317","254.77689","219.90581","0.00723"
"52.80000","4.61658","256.14081","221.08305","0.00729"
"53.20000","4.64979","258.31720","222.96156","0.00734"
"53.60000","4.68322","260.02798","224.43819","0.00739"
"54.00000","4.71647","261.81006","225.97636","0.00744"
"54.40000","4.74989","263.13315","227.11836","0.00750"
"54.80000","4.78324","265.01474","228.74242","0.00755"
"55.20000","4.81650","266.60880","230.11830","0.00760"
"55.60000","4.84988","268.60056","231.83745","0.00765"
"56.00000","4.88313","270.19287","233.21182","0.00771"
"56.40000","4.91656","272.18015","234.92709","0.00776"
"56.80000","4.94984","273.62912","236.17775","0.00781"
"57.20000","4.98325","275.20493","237.53789","0.00786"
"57.60000","5.01653","277.42087","239.45053","0.00792"
"58.00000","5.04987","278.81363","240.65266","0.00797"
"58.40000","5.08316","280.81454","242.37971","0.00802"
"58.80000","5.11658","282.42270","243.76776","0.00808"
"59.20000","5.14982","283.95685","245.09193","0.00813"
"59.60000","5.18329","285.95401","246.81575","0.00818"
"60.00000","5.21652","287.42349","248.08411","0.00823"
"60.40000","5.24989","288.99115","249.43719","0.00829"
"60.80000","5.28321","290.77667","250.97833","0.00834"
"61.20000","5.31652","292.41397","252.39154","0.00839"
"61.60000","5.34991","293.86292","253.64217","0.00844"
"62.00000","5.38322","295.72388","255.24843","0.00850"
"62.40000","5.41659","297.29877","256.60776","0.00855"
"62.80000","5.44984","299.38025","258.40436","0.00860"
"63.20000","5.48324","300.70087","259.54422","0.00865"
"63.60000","5.51653","302.60001","261.18341","0.00871"
"64.00000","5.54991","304.28571","262.63840","0.00876"
"64.40000","5.58323","306.27618","264.35645","0.00881"
"64.80000","5.61657","307.60693","265.50507","0.00886"
"65.20000","5.64992","309.14880","266.83588","0.00892"
"65.60000","5.68321","311.13809","268.55292","0.00897"
"66.00000","5.71654","312.73907","269.93475","0.00902"
"66.40000","5.74987","314.66010","271.59286","0.00907"
"66.80000","5.78329","316.35190","273.05310","0.00913"
"67.20000","5.81654","317.84894","274.34525","0.00918"
"67.60000","5.84990","319.36728","275.65576","0.00923"
"68.00000","5.88319","321.34406","277.36200","0.00929"
"68.40000","5.91658","322.83496","278.64883","0.00934"
"68.80000","5.94987","324.48822","280.07581","0.00939"
"69.20000","5.98327","325.85034","281.25150","0.00944"
"69.60000","6.01652","327.56516","282.73163","0.00950"
"70.00000","6.04990","329.37204","284.29120","0.00955"
"70.40000","6.08319","330.87662","285.58984","0.00960"
"70.80000","6.11655","332.76010","287.21555","0.00965"
"71.20000","6.14983","334.26767","288.51675","0.00971"
"71.60000","6.18324","336.44388","290.39511","0.00976"
"72.00000","6.21659","337.45593","291.26865","0.00981"
"72.40000","6.24981","339.40308","292.94928","0.00986"
"72.80000","6.28325","340.72650","294.09158","0.00992"
"73.20000","6.31644","342.43497","295.56622","0.00997"
"73.60000","6.34991","344.04596","296.95670","0.01002"
"74.00000","6.38319","345.68518","298.37158","0.01007"
"74.40000","6.41655","347.72318","300.13062","0.01013"
"74.80000","6.44987","348.91379","301.15826","0.01018"
"75.20000","6.48317","350.95044","302.91617","0.01023"
"75.60000","6.51653","352.68158","304.41037","0.01028"
"76.00000","6.54983","354.01642","305.56253","0.01034"
"76.40000","6.58320","355.61349","306.94101","0.01039"
"76.80000","6.61653","357.54929","308.61185","0.01044"
"77.20000","6.64988","358.72653","309.62796","0.01050"
"77.60000","6.68316","360.84818","311.45923","0.01055"
"78.00000","6.71656","362.47754","312.86557","0.01060"
"78.40000","6.74979","364.04614","314.21948","0.01065"
"78.80000","6.78327","365.65393","315.60721","0.01071"
"79.20000","6.81644","367.06821","316.82791","0.01076"
"79.60000","6.84993","368.94333","318.44638","0.01081"
"80.00000","6.88318","370.47699","319.77014","0.01086"
"80.40000","6.91650","371.81116","320.92169","0.01092"
"80.80000","6.94987","374.13419","322.92679","0.01097"
"81.20000","6.98320","375.35175","323.97769","0.01102"
"81.60000","7.01657","377.07510","325.46518","0.01107"
"82.00000","7.04982","378.51016","326.70383","0.01113"
"82.40000","7.08325","380.04044","328.02466","0.01118"
"82.80000","7.11647","381.95743","329.67926","0.01123"
"83.20000","7.14993","383.40063","330.92496","0.01128"
"83.60000","7.18316","384.85577","332.18091","0.01134"
"84.00000","7.21659","386.51154","333.61005","0.01139"
"84.40000","7.24989","388.17126","335.04263","0.01144"
"84.80000","7.28319","389.69666","336.35922","0.01149"
"85.20000","7.31654","391.45184","337.87418","0.01155"
"85.60000","7.34988","392.73569","338.98230","0.01160"
"86.00000","7.38326","394.56485","340.56113","0.01165"
"86.40000","7.41654","396.03772","341.83240","0.01171"
"86.80000","7.44990","397.52625","343.11719","0.01176"
"87.20000","7.48321","399.18832","344.55179","0.01181"
"87.60000","7.51658","400.69476","345.85205","0.01186"
"88.00000","7.54986","402.35083","347.28143","0.01192"
"88.40000","7.58327","404.09732","348.78888","0.01197"
"88.80000","7.61653","405.49271","349.99329","0.01202"
"89.20000","7.64995","406.85309","351.16748","0.01207"
"89.60000","7.68317","408.52939","352.61435","0.01213"
"90.00000","7.71655","410.04819","353.92526","0.01218"
"90.40000","7.74989","411.64243","355.30130","0.01223"
"90.80000","7.78320","413.36853","356.79117","0.01228"
"91.20000","7.81660","414.87378","358.09039","0.01234"
"91.60000","7.84985","416.21054","359.24420","0.01239"
"92.00000","7.88325","417.75223","360.57486","0.01244"
"92.40000","7.91651","419.43274","362.02536","0.01249"
"92.80000","7.94992","420.95178","363.33649","0.01255"
"93.20000","7.98319","422.55841","364.72324","0.01260"
"93.60000","8.01658","423.64850","365.66412","0.01265"
"94.00000","8.04987","425.38785","367.16541","0.01270"
"94.40000","8.08323","427.07724","368.62357","0.01276"
"94.80000","8.11653","428.44702","369.80588","0.01281"
"95.20000","8.14988","430.16113","371.28537","0.01286"
"95.60000","8.18318","431.62842","372.55182","0.01292"
"96.00000","8.21655","433.14951","373.86475","0.01297"
"96.40000","8.24990","434.67297","375.17969","0.01302"
"96.80000","8.28318","436.34839","376.62579","0.01307"
"97.20000","8.31653","437.79437","377.87387","0.01313"
"97.60000","8.34982","438.95789","378.87811","0.01318"
"98.00000","8.38323","440.83054","380.49448","0.01323"
"98.40000","8.41652","442.29016","381.75430","0.01328"
"98.80000","8.44990","443.35583","382.67413","0.01334"
"99.20000","8.48315","445.23541","384.29645","0.01339"
"99.60000","8.51651","446.68979","385.55176","0.01344"
"100.00000","8.54985","448.17197","386.83109","0.01349"
"100.40000","8.58321","449.69278","388.14374","0.01355"
"100.80000","8.61654","450.98871","389.26230","0.01360"
"101.20000","8.64987","452.96521","390.96829","0.01365"
"101.60000","8.68321","454.13116","391.97464","0.01370"
"102.00000","8.71648","455.69818","393.32718","0.01376"
"102.40000","8.74989","457.04694","394.49133","0.01381"
"102.80000","8.78315","458.73712","395.95020","0.01386"
"103.20000","8.81660","460.34927","397.34171","0.01391"
"103.60000","8.84986","461.63818","398.45419","0.01397"
"104.00000","8.88321","463.19577","399.79858","0.01402"
"104.40000","8.91653","464.36087","400.80423","0.01407"
"104.80000","8.94984","466.02292","402.23880","0.01412"
"105.20000","8.98321","467.57513","403.57855","0.01418"
"105.60000","9.01653","469.19504","404.97675","0.01423"
"106.00000","9.04990","470.24512","405.88309","0.01428"
"106.40000","9.08324","472.04703","407.43839","0.01434"
"106.80000","9.11653","473.61966","408.79578","0.01439"
"107.20000","9.14987","474.87692","409.88095","0.01444"
"107.60000","9.18322","476.27344","411.08633","0.01449"
"108.00000","9.21654","477.58981","412.22253","0.01455"
"108.40000","9.25001","479.31378","413.71054","0.01460"
"108.80000","9.28314","480.90491","415.08389","0.01465"
"109.20000","9.31663","482.45413","416.42108","0.01470"
"109.60000","9.34984","483.41437","417.24988","0.01476"
"110.00000","9.38324","484.90091","418.53296","0.01481"
"110.40000","9.41656","486.67200","420.06165","0.01486"
"110.80000","9.44990","488.04520","421.24689","0.01491"
"111.20000","9.48325","489.30695","422.33597","0.01497"
"111.60000","9.51653","490.85889","423.67548","0.01502"
"112.00000","9.54992","492.56390","425.14713","0.01507"
"112.40000","9.58319","493.65866","426.09204","0.01512"
"112.80000","9.61658","495.15634","427.38474","0.01518"
"113.20000","9.64988","496.76801","428.77582","0.01523"
"113.60000","9.68326","497.80542","429.67126","0.01528"
"114.00000","9.71653","499.23328","430.90369","0.01534"
"114.40000","9.74992","500.85730","432.30542","0.01539"
"114.80000","9.78315","502.43002","433.66290","0.01544"
"115.20000","9.81658","503.60382","434.67603","0.01549"
"115.60000","9.84990","505.20944","436.06189","0.01555"
"116.00000","9.88322","506.60373","437.26535","0.01560"
"116.40000","9.91655","508.01648","438.48474","0.01565"
"116.80000","9.94982","509.33658","439.62415","0.01570"
"117.20000","9.98323","510.76099","440.85361","0.01576"
"117.60000","10.01652","512.41943","442.28506","0.01581"
"118.00000","10.04991","513.32562","443.06723","0.01586"
"118.40000","10.08314","514.92468","444.44742","0.01591"
"118.80000","10.11661","516.66022","445.94540","0.01597"
"119.20000","10.14979","517.60687","446.76248","0.01602"
"119.60000","10.18321","518.90875","447.88620","0.01607"
"120.00000","10.21651","520.60431","449.34967","0.01612"
"120.40000","10.24986","521.79480","450.37723","0.01618"
"120.80000","10.28324","523.47180","451.82471","0.01623"
"121.20000","10.31649","524.83435","453.00076","0.01628"
"121.60000","10.34990","526.21283","454.19055","0.01633"
"122.00000","10.38312","527.63324","455.41656","0.01639"
"122.40000","10.41658","528.92908","456.53503","0.01644"
"122.80000","10.44982","530.18121","457.61578","0.01649"
"123.20000","10.48323","532.03760","459.21811","0.01655"
"123.60000","10.51650","532.84814","459.91769","0.01660"
"124.00000","10.54988","534.36859","461.23004","0.01665"
"124.40000","10.58315","535.60297","462.29547","0.01670"
"124.80000","10.61656","536.99963","463.50098","0.01676"
"125.20000","10.64985","538.31042","464.63239","0.01681"
"125.60000","10.68322","540.06262","466.14474","0.01686"
"126.00000","10.71655","541.40173","467.30057","0.01691"
"126.40000","10.74984","542.42371","468.18268","0.01697"
"126.80000","10.78321","543.85889","469.42142","0.01702"
"127.20000","10.81649","545.05756","470.45602","0.01707"
"127.60000","10.84992","546.34644","471.56851","0.01712"
"128.00000","10.88317","548.02606","473.01825","0.01718"
"128.40000","10.91659","549.24243","474.06812","0.01723"
"128.80000","10.94985","550.60175","475.24139","0.01728"
"129.20000","10.98322","552.28314","476.69266","0.01733"
"129.60000","11.01654","553.36920","477.63007","0.01739"
"130.00000","11.04986","554.90265","478.95364","0.01744"
"130.40000","11.08324","556.07849","479.96854","0.01749"
"130.80000","11.11653","557.58978","481.27298","0.01754"
"131.20000","11.14991","558.42340","481.99249","0.01760"
"131.60000","11.18318","560.13062","483.46606","0.01765"
"132.00000","11.21660","561.70447","484.82449","0.01770"
"132.40000","11.24984","562.73212","485.71149","0.01775"
"132.80000","11.28329","563.80170","486.63467","0.01781"
"133.20000","11.31653","565.36285","487.98215","0.01786"
"133.60000","11.34990","566.85150","489.26706","0.01791"
"134.00000","11.38319","568.10345","490.34766","0.01797"
"134.40000","11.41658","569.28979","491.37161","0.01802"
"134.80000","11.44990","570.54279","492.45312","0.01807"
"135.20000","11.48323","571.76385","493.50705","0.01812"
"135.60000","11.51657","573.33313","494.86154","0.01818"
"136.00000","11.54989","574.29974","495.69586","0.01823"
"136.40000","11.58321","575.41809","496.66113","0.01828"
"136.80000","11.61657","577.07898","498.09470","0.01833"
"137.20000","11.64985","578.81012","499.58890","0.01839"
"137.60000","11.68321","579.51587","500.19806","0.01844"
"138.00000","11.71662","580.78589","501.29425","0.01849"
"138.40000","11.74982","582.47711","502.75400","0.01854"
"138.80000","11.78325","583.77240","503.87201","0.01860"
"139.20000","11.81649","585.08228","505.00259","0.01865"
"139.60000","11.84989","586.17395","505.94485","0.01870"
"140.00000","11.88323","587.31036","506.92572","0.01875"
"140.40000","11.91652","588.83130","508.23849","0.01881"
"140.80000","11.94989","589.71289","508.99942","0.01886"
"141.20000","11.98314","591.32471","510.39062","0.01891"
"141.60000","12.01656","592.57959","511.47375","0.01897"
"142.00000","12.04983","593.82489","512.54865","0.01902"
"142.40000","12.08323","595.20056","513.73602","0.01907"
"142.80000","12.11655","596.69165","515.02301","0.01912"
"143.20000","12.14986","597.71930","515.91003","0.01918"
"143.60000","12.18317","598.93127","516.95612","0.01923"
"144.00000","12.21655","600.19464","518.04657","0.01928"
"144.40000","12.24977","601.65240","519.30481","0.01933"
"144.80000","12.28325","603.01996","520.48517","0.01939"
"145.20000","12.31648","603.83417","521.18793","0.01944"
"145.60000","12.34988","605.00714","522.20038","0.01949"
"146.00000","12.38319","606.66486","523.63116","0.01954"
"146.40000","12.41649","608.01483","524.79639","0.01960"
"146.80000","12.44988","608.68408","525.37402","0.01965"
"147.20000","12.48320","610.31342","526.78040","0.01970"
"147.60000","12.51658","611.20538","527.55029","0.01975"
"148.00000","12.54980","612.58667","528.74249","0.01981"
"148.40000","12.58324","614.09888","530.04773","0.01986"
"148.80000","12.61649","615.26147","531.05121","0.01991"
"149.20000","12.64990","616.42792","532.05798","0.01996"
"149.60000","12.68319","617.73291","533.18439","0.02002"
"150.00000","12.71659","618.78149","534.08942","0.02007"
"150.40000","12.74984","620.24640","535.35382","0.02012"
"150.80000","12.78321","621.14514","536.12958","0.02017"
"151.20000","12.81652","622.36542","537.18286","0.02023"
"151.60000","12.84985","623.74493","538.37354","0.02028"
"152.00000","12.88326","624.76282","539.25208","0.02033"
"152.40000","12.91655","626.34650","540.61902","0.02039"
"152.80000","12.94989","627.21088","541.36511","0.02044"
"153.20000","12.98321","628.55841","542.52820","0.02049"
"153.60000","13.01656","630.00171","543.77393","0.02054"
"154.00000","13.04986","630.95758","544.59900","0.02060"
"154.40000","13.08327","632.03296","545.52716","0.02065"
"154.80000","13.11655","633.33246","546.64880","0.02070"
"155.20000","13.14994","634.31989","547.50110","0.02075"
"155.60000","13.18320","635.59064","548.59796","0.02081"
"156.00000","13.21654","636.73273","549.58368","0.02086"
"156.40000","13.24992","637.93689","550.62305","0.02091"
"156.80000","13.28318","639.34937","551.84222","0.02096"
"157.20000","13.31665","640.55396","552.88190","0.02102"
"157.60000","13.34983","641.91022","554.05255","0.02107"
"158.00000","13.38330","642.77612","554.79993","0.02112"
"158.40000","13.41648","643.82922","555.70892","0.02117"
"158.80000","13.44994","645.37488","557.04303","0.02123"
"159.20000","13.48320","646.22418","557.77606","0.02128"
"159.60000","13.51660","647.64679","559.00397","0.02133"
"160.00000","13.54989","648.49243","559.73389","0.02138"
"160.40000","13.58323","649.93866","560.98218","0.02144"
"160.80000","13.61655","650.97479","561.87646","0.02149"
"161.20000","13.64986","651.96942","562.73499","0.02154"
"161.60000","13.68324","653.41504","563.98273","0.02160"
"162.00000","13.71652","654.19250","564.65381","0.02165"
"162.40000","13.74993","655.58221","565.85327","0.02170"
"162.80000","13.78319","656.63367","566.76080","0.02175"
"163.20000","13.81655","657.83136","567.79462","0.02181"
"163.60000","13.84980","659.19751","568.97375","0.02186"
"164.00000","13.88323","660.09753","569.75061","0.02191"
"164.40000","13.91655","661.41608","570.88867","0.02196"
"164.80000","13.94991","662.33606","571.68274","0.02202"
"165.20000","13.98318","663.76019","572.91193","0.02207"
"165.60000","14.01651","664.69409","573.71802","0.02212"
"166.00000","14.04986","665.86255","574.72656","0.02217"
"166.40000","14.08320","667.37292","576.03021","0.02223"
"166.80000","14.11656","668.22241","576.76343","0.02228"
"167.20000","14.14983","669.25140","577.65155","0.02233"
"167.60000","14.18324","670.38135","578.62689","0.02238"
"168.00000","14.21646","671.66003","579.73053","0.02244"
"168.40000","14.24989","673.03479","580.91711","0.02249"
"168.80000","14.28313","673.66486","581.46094","0.02254"
"169.20000","14.31656","675.18256","582.77094","0.02259"
"169.60000","14.34989","676.26648","583.70648","0.02265"
"170.00000","14.38317","677.26794","584.57092","0.02270"
"170.40000","14.41655","678.16095","585.34167","0.02275"
"170.80000","14.44981","679.18347","586.22424","0.02281"
"171.20000","14.48324","680.20337","587.10455","0.02286"
"171.60000","14.51652","681.35596","588.09937","0.02291"
"172.00000","14.54991","682.92737","589.45575","0.02296"
"172.40000","14.58323","683.80908","590.21674","0.02302"
"172.80000","14.61653","685.20514","591.42175","0.02307"
"173.20000","14.64985","686.06201","592.16132","0.02312"
"173.60000","14.68321","687.29565","593.22614","0.02317"
"174.00000","14.71651","688.28284","594.07819","0.02323"
"174.40000","14.74997","689.16602","594.84052","0.02328"
"174.80000","14.78317","690.23627","595.76428","0.02333"
"175.20000","14.81657","691.37689","596.74878","0.02338"
"175.60000","14.84987","692.65100","597.84851","0.02344"
"176.00000","14.88319","693.62219","598.68677","0.02349"
"176.40000","14.91659","694.66504","599.58685","0.02354"
"176.80000","14.94987","695.66547","600.45038","0.02359"
"177.20000","14.98326","696.72644","601.36615","0.02365"
"177.60000","15.01652","697.83221","602.32056","0.02370"
"178.00000","15.04992","699.29364","603.58197","0.02375"
"178.40000","15.08321","699.94421","604.14349","0.02380"
"178.80000","15.11656","701.09674","605.13824","0.02386"
"179.20000","15.14991","701.94348","605.86914","0.02391"
"179.60000","15.18325","703.28748","607.02917","0.02396"
"180.00000","15.21656","704.31561","607.91656","0.02402"
"180.40000","15.24991","705.29865","608.76508","0.02407"
"180.80000","15.28319","706.44427","609.75391","0.02412"
"181.20000","15.31655","707.25452","610.45325","0.02417"
"181.60000","15.34994","708.34625","611.39557","0.02423"
"182.00000","15.38320","709.67218","612.53998","0.02428"
"182.40000","15.41657","710.49847","613.25317","0.02433"
"182.80000","15.44987","711.65198","614.24884","0.02438"
"183.20000","15.48324","712.76379","615.20850","0.02444"
"183.60000","15.51651","713.66650","615.98761","0.02449"
"184.00000","15.54993","714.73053","616.90601","0.02454"
"184.40000","15.58317","716.05798","618.05176","0.02459"
"184.80000","15.61659","717.09094","618.94336","0.02465"
"185.20000","15.64983","717.94299","619.67877","0.02470"
"185.60000","15.68321","718.80615","620.42383","0.02475"
"186.00000","15.71649","719.94104","621.40338","0.02480"
"186.40000","15.74990","721.25214","622.53503","0.02486"
"186.80000","15.78322","722.08722","623.25580","0.02491"
"187.20000","15.81649","722.87585","623.93652","0.02496"
"187.60000","15.84991","724.07281","624.96960","0.02501"
"188.00000","15.88311","725.09619","625.85297","0.02507"
"188.40000","15.91658","726.18970","626.79675","0.02512"
"188.80000","15.94985","726.89447","627.40509","0.02517"
"189.20000","15.98321","728.07013","628.41986","0.02523"
"189.60000","16.01652","728.89709","629.13361","0.02528"
"190.00000","16.04985","729.93365","630.02832","0.02533"
"190.40000","16.08319","730.94427","630.90057","0.02538"
"190.80000","16.11650","731.83417","631.66870","0.02544"
"191.20000","16.14987","732.93671","632.62036","0.02549"
"191.60000","16.18320","734.11871","633.64056","0.02554"
"192.00000","16.21651","735.20294","634.57642","0.02559"
"192.40000","16.24982","735.98132","635.24823","0.02565"
"192.80000","16.28322","736.76086","635.92108","0.02570"
"193.20000","16.31647","738.32422","637.27045","0.02575"
"193.60000","16.34995","739.35590","638.16095","0.02580"
"194.00000","16.38314","740.04614","638.75671","0.02586"
"194.40000","16.41659","741.08337","639.65198","0.02591"
"194.80000","16.44983","741.67957","640.16656","0.02596"
"195.20000","16.48320","743.02020","641.32373","0.02601"
"195.60000","16.51653","743.67352","641.88763","0.02607"
"196.00000","16.54987","744.57080","642.66211","0.02612"
"196.40000","16.58324","745.98181","643.87994","0.02617"
"196.80000","16.61651","746.84796","644.62756","0.02622"
"197.20000","16.64991","748.08691","645.69696","0.02628"
"197.60000","16.68315","748.74829","646.26782","0.02633"
"198.00000","16.71662","749.61926","647.01959","0.02638"
"198.40000","16.74985","750.67334","647.92938","0.02644"
"198.80000","16.78328","751.65161","648.77374","0.02649"
"199.20000","16.81653","752.93787","649.88397","0.02654"
"199.60000","16.84989","753.76257","650.59576","0.02659"
"200.00000","16.88315","754.52661","651.25525","0.02665"
"200.40000","16.91658","755.79718","652.35193","0.02670"
"200.80000","16.94993","756.71216","653.14166","0.02675"
"201.20000","16.98323","757.52142","653.84015","0.02680"
"201.60000","17.01658","758.58069","654.75446","0.02686"
"202.00000","17.04988","759.61499","655.64716","0.02691"
"202.40000","17.08322","760.48969","656.40216","0.02696"
"202.80000","17.11656","761.10846","656.93622","0.02701"
"203.20000","17.14990","762.33527","657.99512","0.02707"
"203.60000","17.18320","763.15442","658.70215","0.02712"
"204.00000","17.21663","764.45483","659.82458","0.02717"
"204.40000","17.24986","765.19324","660.46191","0.02722"
"204.80000","17.28324","766.25592","661.37915","0.02728"
"205.20000","17.31652","767.09650","662.10468","0.02733"
"205.60000","17.34988","768.31061","663.15265","0.02738"
"206.00000","17.38329","768.84741","663.61597","0.02743"
"206.40000","17.41652","770.06335","664.66547","0.02749"
"206.80000","17.44992","770.87177","665.36328","0.02754"
"207.20000","17.48310","771.68616","666.06616","0.02759"
"207.60000","17.51660","772.83575","667.05841","0.02765"
"208.00000","17.54984","773.73651","667.83588","0.02770"
"208.40000","17.58323","774.43182","668.43604","0.02775"
"208.80000","17.61654","775.55048","669.40161","0.02780"
"209.20000","17.64987","776.17987","669.94482","0.02786"
"209.60000","17.68318","777.25739","670.87488","0.02791"
"210.00000","17.71655","778.48645","671.93573","0.02796"
"210.40000","17.74983","779.37714","672.70453","0.02801"
"210.80000","17.78323","780.24396","673.45270","0.02807"
"211.20000","17.81655","781.14423","674.22974","0.02812"
"211.60000","17.84984","782.13855","675.08795","0.02817"
"212.00000","17.88320","783.16919","675.97754","0.02822"
"212.40000","17.91648","783.93518","676.63867","0.02828"
"212.80000","17.94987","785.32043","677.83435","0.02833"
"213.20000","17.98317","786.12506","678.52887","0.02838"
"213.60000","18.01657","786.54376","678.89026","0.02843"
"214.00000","18.04980","787.70178","679.88977","0.02849"
"214.40000","18.08320","788.60425","680.66870","0.02854"
"214.80000","18.11648","789.35828","681.31952","0.02859"
"215.20000","18.14988","790.71613","682.49152","0.02864"
"215.60000","18.18318","791.39221","683.07507","0.02870"
"216.00000","18.21657","792.39581","683.94135","0.02875"
"216.40000","18.24986","793.19318","684.62958","0.02880"
"216.80000","18.28317","794.26862","685.55780","0.02886"
"217.20000","18.31656","795.00952","686.19733","0.02891"
"217.60000","18.34982","796.11914","687.15503","0.02896"
"218.00000","18.38325","797.02936","687.94067","0.02901"
"218.40000","18.41656","797.58502","688.42029","0.02907"
"218.80000","18.44988","798.76056","689.43494","0.02912"
"219.20000","18.48320","799.73853","690.27905","0.02917"
"219.60000","18.51652","800.85028","691.23865","0.02922"
"220.00000","18.54987","801.46246","691.76703","0.02928"
"220.40000","18.58324","802.69043","692.82690","0.02933"
"220.80000","18.61655","803.70123","693.69940","0.02938"
"221.20000","18.64989","804.28497","694.20325","0.02943"
"221.60000","18.68324","805.13751","694.93909","0.02949"
"222.00000","18.71652","805.89948","695.59674","0.02954"
"222.40000","18.74990","807.20190","696.72095","0.02959"
"222.80000","18.78319","807.95709","697.37274","0.02964"
"223.20000","18.81665","808.83771","698.13281","0.02970"
"223.60000","18.84982","809.73810","698.90997","0.02975"
"224.00000","18.88330","810.30719","699.40118","0.02980"
"224.40000","18.91650","811.53021","700.45685","0.02985"
"224.80000","18.94993","812.58667","701.36865","0.02991"
"225.20000","18.98322","812.94312","701.67633","0.02996"
"225.60000","19.01657","813.79620","702.41266","0.03001"
"226.00000","19.04990","814.69470","703.18817","0.03007"
"226.40000","19.08322","816.26166","704.54065","0.03012"
"226.80000","19.11657","816.66467","704.88855","0.03017"
"227.20000","19.14986","817.67163","705.75769","0.03022"
"227.60000","19.18324","818.77533","706.71033","0.03028"
"228.00000","19.21655","819.64465","707.46063","0.03033"
"228.40000","19.24994","820.58679","708.27380","0.03038"
"228.80000","19.28322","821.44727","709.01654","0.03043"
"229.20000","19.31659","822.23334","709.69501","0.03049"
"229.60000","19.34980","822.84119","710.21967","0.03054"
"230.00000","19.38326","823.65625","710.92316","0.03059"
"230.40000","19.41653","824.28369","711.46472","0.03064"
"230.80000","19.44990","825.30487","712.34613","0.03070"
"231.20000","19.48321","826.35712","713.25439","0.03075"
"231.60000","19.51648","827.43683","714.18634","0.03080"
"232.00000","19.54989","828.27112","714.90643","0.03085"
"232.40000","19.58318","828.78644","715.35120","0.03091"
"232.80000","19.61657","829.72052","716.15741","0.03096"
"233.20000","19.64982","830.73859","717.03613","0.03101"
"233.60000","19.68326","831.16595","717.40503","0.03106"
"234.00000","19.71645","831.67529","717.84467","0.03112"
"234.40000","19.74991","833.13940","719.10840","0.03117"
"234.80000","19.78314","834.05261","719.89661","0.03122"
"235.20000","19.81656","834.67120","720.43054","0.03128"
"235.60000","19.84985","835.48969","721.13696","0.03133"
"236.00000","19.88317","836.36078","721.88885","0.03138"
"236.40000","19.91657","837.31555","722.71295","0.03143"
"236.80000","19.94977","837.96710","723.27533","0.03149"
"237.20000","19.98326","838.66010","723.87347","0.03154"
"237.60000","20.01648","839.42126","724.53046","0.03159"
"238.00000","20.04992","840.21558","725.21606","0.03164"
"238.40000","20.08318","840.96759","725.86511","0.03170"
"238.80000","20.11652","841.74310","726.53448","0.03175"
"239.20000","20.14981","842.50360","727.19092","0.03180"
"239.60000","20.18323","843.34399","727.91626","0.03185"
"240.00000","20.21650","844.32349","728.76172","0.03191"
"240.40000","20.24991","845.03784","729.37830","0.03196"
"240.80000","20.28320","845.50793","729.78406","0.03201"
"241.20000","20.31652","846.67511","730.79144","0.03206"
"241.60000","20.34987","847.26239","731.29834","0.03212"
"242.00000","20.38318","848.03082","731.96161","0.03217"
"242.40000","20.41660","848.66406","732.50818","0.03222"
"242.80000","20.44981","849.31378","733.06897","0.03227"
"243.20000","20.48328","850.63397","734.20850","0.03233"
"243.60000","20.51649","851.11121","734.62042","0.03238"
"244.00000","20.54991","851.97943","735.36981","0.03243"
"244.40000","20.58322","852.57709","735.88562","0.03249"
"244.80000","20.61653","853.52350","736.70251","0.03254"
"245.20000","20.64990","854.35382","737.41919","0.03259"
"245.60000","20.68324","855.11310","738.07458","0.03264"
"246.00000","20.71658","855.66266","738.54889","0.03270"
"246.40000","20.74986","856.54840","739.31342","0.03275"
"246.80000","20.78325","857.34979","740.00513","0.03280"
"247.20000","20.81652","857.85541","740.44153","0.03285"
"247.60000","20.84995","858.42969","740.93719","0.03291"
"248.00000","20.88319","859.28583","741.67615","0.03296"
"248.40000","20.91657","859.97034","742.26697","0.03301"
"248.80000","20.94986","860.75183","742.94153","0.03306"
"249.20000","20.98323","861.23822","743.36133","0.03312"
"249.60000","21.01654","862.21283","744.20258","0.03317"
"250.00000","21.04992","862.96387","744.85077","0.03322"
"250.40000","21.08322","863.62036","745.41742","0.03327"
"250.80000","21.11656","864.17389","745.89520","0.03333"
"251.20000","21.14987","864.66882","746.32239","0.03338"
"251.60000","21.18323","866.03967","747.50562","0.03343"
"252.00000","21.21652","866.72644","748.09839","0.03348"
"252.40000","21.24988","867.44806","748.72125","0.03354"
"252.80000","21.28328","868.21204","749.38068","0.03359"
"253.20000","21.31647","868.66278","749.76971","0.03364"
"253.60000","21.34992","869.55365","750.53864","0.03370"
"254.00000","21.38317","870.36664","751.24036","0.03375"
"254.40000","21.41654","870.86963","751.67450","0.03380"
"254.80000","21.44989","871.06750","751.84528","0.03385"
"255.20000","21.48320","871.86609","752.53461","0.03391"
"255.60000","21.51653","872.65491","753.21545","0.03396"
"256.00000","21.54982","873.50940","753.95294","0.03401"
"256.40000","21.58319","873.97174","754.35205","0.03406"
"256.80000","21.61652","874.85333","755.11298","0.03412"
"257.20000","21.64988","875.41431","755.59717","0.03417"
"257.60000","21.68319","876.13629","756.22034","0.03422"
"258.00000","21.71653","876.86633","756.85046","0.03427"
"258.40000","21.74981","877.38763","757.30042","0.03433"
"258.80000","21.78323","878.19080","757.99365","0.03438"
"259.20000","21.81647","879.30115","758.95203","0.03443"
"259.60000","21.84992","879.54822","759.16528","0.03448"
"260.00000","21.88314","880.38458","759.88715","0.03454"
"260.40000","21.91656","881.28369","760.66321","0.03459"
"260.80000","21.94982","881.64288","760.97321","0.03464"
"261.20000","21.98318","882.47937","761.69525","0.03469"
"261.60000","22.01654","882.95129","762.10254","0.03475"
"262.00000","22.04984","883.77161","762.81061","0.03480"
"262.40000","22.08324","884.35699","763.31586","0.03485"
"262.80000","22.11647","885.00555","763.87567","0.03491"
"263.20000","22.14990","885.47601","764.28174","0.03496"
"263.60000","22.18313","886.20154","764.90796","0.03501"
"264.00000","22.21656","887.36414","765.91144","0.03506"
"264.40000","22.24985","887.77222","766.26367","0.03512"
"264.80000","22.28328","888.49817","766.89026","0.03517"
"265.20000","22.31649","888.90216","767.23895","0.03522"
"265.60000","22.34990","889.70111","767.92853","0.03527"
"266.00000","22.38318","889.88324","768.08575","0.03533"
"266.40000","22.41654","891.07501","769.11438","0.03538"
"266.67500","22.43946","54.57566","47.10594","0.03541"
"267.07500","22.47282","58.73153","50.69300","0.03547"
"267.47500","22.50604","60.48523","52.20668","0.03552"
"267.87500","22.53949","61.90430","53.43151","0.03557"
"268.27500","22.57274","63.56477","54.86472","0.03563"
"268.67500","22.60616","64.29294","55.49322","0.03568"
"269.07500","22.63942","65.71661","56.72203","0.03573"
"269.47500","22.67282","66.56379","57.45327","0.03578"
"269.65300","22.68767","67.09032","57.90773","0.03581"