File: Specimen_RawData_1_trimmed.csv
Time(s),Extension(mm),Load(N),Flexure stress(MPa),Flexure strain (Extension)(mm/mm)
0.00000,0.20005,10.03282,8.33135,0.00032
0.30000,0.22319,11.31751,9.39817,0.00036
0.60000,0.24816,13.13026,10.90350,0.00040
0.90000,0.27318,14.07944,11.69171,0.00044
1.20000,0.29817,15.71863,13.05291,0.00048
1.50000,0.32318,17.26521,14.33721,0.00052
1.80000,0.34823,18.61882,15.46126,0.00056
2.10000,0.37318,19.89490,16.52093,0.00060
2.40000,0.39815,21.61106,17.94605,0.00064
2.70000,0.42318,22.87559,18.99612,0.00068
3.00000,0.44819,24.40991,20.27024,0.00072
3.30000,0.47317,25.36870,21.06643,0.00076
3.60000,0.49818,27.02603,22.44269,0.00080
3.90000,0.52320,28.58545,23.73765,0.00084
4.20000,0.54821,29.79378,24.74106,0.00088
4.50000,0.57322,31.53042,26.18319,0.00092
4.80000,0.59816,32.67811,27.13624,0.00096
5.10000,0.62314,34.41809,28.58114,0.00101
5.40000,0.64822,35.55389,29.52432,0.00105
5.70000,0.67316,37.06113,30.77594,0.00109
6.00000,0.69812,38.48333,31.95695,0.00113
6.30000,0.72318,39.85413,33.09528,0.00117
6.60000,0.74812,41.36761,34.35209,0.00121
6.90000,0.77320,42.70131,35.45960,0.00125
7.20000,0.79822,44.01864,36.55354,0.00129
7.50000,0.82313,45.52505,37.80447,0.00133
7.80000,0.84823,47.07431,39.09100,0.00137
8.10000,0.87324,48.55443,40.32010,0.00141
8.40000,0.89812,50.11269,41.61410,0.00145
8.70000,0.92322,51.52127,42.78379,0.00149
9.00000,0.94822,52.82137,43.86341,0.00153
9.30000,0.97317,54.27297,45.06884,0.00157
9.60000,0.99826,55.86473,46.39064,0.00161
9.90000,1.02317,57.22787,47.52261,0.00165
10.20000,1.04814,58.78540,48.81600,0.00169
10.50000,1.07323,60.01558,49.83755,0.00173
10.80000,1.09819,61.46632,51.04226,0.00177
11.10000,1.12315,62.92582,52.25425,0.00181
11.40000,1.14821,64.59415,53.63965,0.00185
11.70000,1.17319,65.82815,54.66437,0.00189
12.00000,1.19819,67.26254,55.85551,0.00193
12.30000,1.22317,68.96452,57.26884,0.00197
12.60000,1.24811,69.98611,58.11718,0.00201
12.90000,1.27317,71.65250,59.50097,0.00205
13.20000,1.29820,73.10691,60.70873,0.00209
13.50000,1.32311,74.51919,61.88150,0.00213
13.80000,1.34818,76.31163,63.36996,0.00217
14.10000,1.37323,77.70770,64.52927,0.00221
14.40000,1.39821,79.06305,65.65477,0.00226
14.70000,1.42322,80.58756,66.92074,0.00230
15.00000,1.44822,81.91341,68.02174,0.00234
15.30000,1.47316,83.30582,69.17802,0.00238
15.60000,1.49824,84.58739,70.24224,0.00242
15.90000,1.52326,86.36002,71.71426,0.00246
16.20000,1.54811,87.64857,72.78427,0.00250
16.50000,1.57321,88.96819,73.88010,0.00254
16.80000,1.59826,90.65717,75.28265,0.00258
17.10000,1.62314,92.18810,76.55395,0.00262
17.40000,1.64819,93.36368,77.53016,0.00266
17.70000,1.67320,94.94388,78.84238,0.00270
18.00000,1.69813,96.19814,79.88392,0.00274
18.30000,1.72322,97.63560,81.07761,0.00278
18.60000,1.74820,99.01069,82.21950,0.00282
18.90000,1.77311,100.70814,83.62907,0.00286
19.20000,1.79822,102.04908,84.74261,0.00290
19.50000,1.82319,103.53973,85.98045,0.00294
19.80000,1.84812,105.08508,87.26373,0.00298
20.10000,1.87318,106.36096,88.32323,0.00302
20.40000,1.89815,107.65005,89.39371,0.00306
20.70000,1.92316,109.26548,90.73518,0.00310
21.00000,1.94819,110.56598,91.81512,0.00314
21.30000,1.97313,112.01056,93.01472,0.00318
21.60000,1.99819,113.53528,94.28086,0.00322
21.90000,2.02321,115.19444,95.65865,0.00326
22.20000,2.04816,116.23589,96.52348,0.00330
22.50000,2.07320,118.04102,98.02248,0.00334
22.80000,2.09818,119.11942,98.91799,0.00338
23.10000,2.12318,120.59760,100.14549,0.00342
23.40000,2.14823,121.84281,101.17953,0.00346
23.70000,2.17317,123.74863,102.76213,0.00350
24.00000,2.19814,124.55500,103.43176,0.00355
24.30000,2.22322,126.07321,104.69249,0.00359
24.60000,2.24824,127.87926,106.19226,0.00363
24.90000,2.27315,129.10883,107.21329,0.00367
25.20000,2.29818,130.67862,108.51687,0.00371
25.50000,2.32319,131.95363,109.57565,0.00375
25.80000,2.34815,133.27368,110.67184,0.00379
26.10000,2.37318,134.49446,111.68559,0.00383
26.40000,2.39817,136.15027,113.06059,0.00387
26.70000,2.42313,137.61584,114.27761,0.00391
27.00000,2.44820,138.93999,115.37720,0.00395
27.30000,2.47320,140.44229,116.62473,0.00399
27.60000,2.49809,141.95828,117.88362,0.00403
27.90000,2.52319,143.28087,118.98191,0.00407
28.20000,2.54818,144.98763,120.39922,0.00411
28.50000,2.57315,145.82899,121.09790,0.00415
28.80000,2.59823,147.42979,122.42722,0.00419
29.10000,2.62317,148.90761,123.65441,0.00423
29.40000,2.64818,150.35289,124.85459,0.00427
29.70000,2.67326,151.47276,125.78454,0.00431
30.00000,2.69818,153.04089,127.08673,0.00435
30.30000,2.72314,154.52814,128.32176,0.00439
30.60000,2.74823,155.58340,129.19806,0.00443
30.90000,2.77318,157.36787,130.67990,0.00447
31.20000,2.79820,158.79997,131.86913,0.00451
31.50000,2.82320,159.87955,132.76562,0.00455
31.80000,2.84814,161.41438,134.04016,0.00459
32.10000,2.87324,162.84410,135.22742,0.00463
32.40000,2.89819,164.37213,136.49631,0.00467
32.70000,2.92311,165.79724,137.67973,0.00471
33.00000,2.94817,167.01601,138.69182,0.00475
33.30000,2.97319,168.48999,139.91582,0.00480
33.60000,2.99813,169.66220,140.88924,0.00484
33.90000,3.02317,171.22389,142.18608,0.00488
34.20000,3.04816,172.48598,143.23413,0.00492
34.50000,3.07316,174.11275,144.58502,0.00496
34.80000,3.09824,175.44684,145.69286,0.00500
35.10000,3.12316,176.80585,146.82140,0.00504
35.40000,3.14816,178.38196,148.13022,0.00508
35.70000,3.17322,179.83226,149.33456,0.00512
36.00000,3.19821,181.39426,150.63165,0.00516
36.30000,3.22315,182.66290,151.68515,0.00520
36.60000,3.24822,184.07693,152.85938,0.00524
36.90000,3.27317,185.19965,153.79169,0.00528
37.20000,3.29817,186.91235,155.21394,0.00532
37.50000,3.32323,188.10730,156.20624,0.00536
37.80000,3.34817,189.58727,157.43521,0.00540
38.10000,3.37311,190.91885,158.54099,0.00544
38.40000,3.39822,192.20088,159.60559,0.00548
38.70000,3.42316,193.65823,160.81580,0.00552
39.00000,3.44812,195.08336,161.99924,0.00556
39.30000,3.47319,196.28598,162.99789,0.00560
39.60000,3.49817,197.90103,164.33905,0.00564
39.90000,3.52316,199.15074,165.37683,0.00568
40.20000,3.54819,200.60974,166.58839,0.00572
40.50000,3.57311,201.63292,167.43805,0.00576
40.80000,3.59818,203.39119,168.89813,0.00580
41.10000,3.62321,204.87538,170.13063,0.00584
41.40000,3.64812,206.16263,171.19957,0.00588
41.70000,3.67319,207.36357,172.19684,0.00592
42.00000,3.69819,208.76788,173.36301,0.00596
42.30000,3.72319,209.98332,174.37231,0.00600
42.60000,3.74824,211.60701,175.72064,0.00605
42.90000,3.77318,212.81277,176.72192,0.00609
43.20000,3.79815,214.21835,177.88913,0.00613
43.50000,3.82325,215.64435,179.07329,0.00617
43.80000,3.84814,217.08006,180.26552,0.00621
44.10000,3.87309,218.49429,181.43991,0.00625
44.40000,3.89820,219.73392,182.46931,0.00629
44.70000,3.92313,221.30122,183.77081,0.00633
45.00000,3.94813,222.19878,184.51616,0.00637
45.30000,3.97318,223.68617,185.75130,0.00641
45.60000,3.99813,225.16846,186.98221,0.00645
45.90000,4.02314,226.68930,188.24513,0.00649
46.20000,4.04822,227.79924,189.16684,0.00653
46.50000,4.07315,229.41597,190.50938,0.00657
46.80000,4.09811,230.60692,191.49835,0.00661
47.10000,4.12321,231.79668,192.48634,0.00665
47.40000,4.14819,233.42116,193.83533,0.00669
47.70000,4.17313,234.75386,194.94202,0.00673
48.00000,4.19819,235.63426,195.67311,0.00677
48.30000,4.22317,237.31639,197.06998,0.00681
48.60000,4.24817,238.64912,198.17670,0.00685
48.90000,4.27322,239.95078,199.25760,0.00689
49.20000,4.29815,241.17381,200.27322,0.00693
49.50000,4.32318,242.42087,201.30879,0.00697
49.80000,4.34827,243.87958,202.52011,0.00701
50.10000,4.37316,245.22998,203.64149,0.00705
50.40000,4.39816,246.86684,205.00076,0.00709
50.70000,4.42317,248.13783,206.05621,0.00713
51.00000,4.44812,249.50549,207.19193,0.00717
51.30000,4.47316,250.75528,208.22977,0.00721
51.60000,4.49811,251.80054,209.09776,0.00725
51.90000,4.52308,253.42233,210.44452,0.00729
52.20000,4.54824,254.57817,211.40433,0.00734
52.50000,4.57318,255.96872,212.55907,0.00738
52.80000,4.59812,257.40256,213.74974,0.00742
53.10000,4.62321,258.63379,214.77216,0.00746
53.40000,4.64814,260.16837,216.04649,0.00750
53.70000,4.67315,261.22183,216.92130,0.00754
54.00000,4.69821,262.52747,218.00551,0.00758
54.30000,4.72312,263.70056,218.97966,0.00762
54.60000,4.74816,265.13455,220.17046,0.00766
54.90000,4.77323,266.45764,221.26917,0.00770
55.20000,4.79816,267.95883,222.51578,0.00774
55.50000,4.82313,269.32208,223.64783,0.00778
55.80000,4.84821,270.37830,224.52492,0.00782
56.10000,4.87318,271.95694,225.83585,0.00786
56.40000,4.89816,273.07629,226.76537,0.00790
56.70000,4.92320,274.38324,227.85066,0.00794
57.00000,4.94817,275.60931,228.86880,0.00798
57.30000,4.97316,276.92545,229.96175,0.00802
57.60000,4.99820,278.25546,231.06621,0.00806
57.90000,5.02314,279.63892,232.21504,0.00810
58.20000,5.04812,281.15897,233.47729,0.00814
58.50000,5.07316,282.26715,234.39755,0.00818
58.80000,5.09816,283.50781,235.42781,0.00822
59.10000,5.12314,284.70523,236.42215,0.00826
59.40000,5.14816,286.20471,237.66734,0.00830
59.70000,5.17315,287.35184,238.61992,0.00834
60.00000,5.19822,288.91257,239.91597,0.00838
60.30000,5.22319,290.23206,241.01169,0.00842
60.60000,5.24811,291.40179,241.98305,0.00846
60.90000,5.27318,292.79858,243.14296,0.00850
61.20000,5.29820,294.07993,244.20700,0.00854
61.50000,5.32313,295.14420,245.09077,0.00859
61.80000,5.34819,296.28354,246.03690,0.00863
62.10000,5.37315,297.67026,247.18845,0.00867
62.40000,5.39816,299.01666,248.30652,0.00871
62.70000,5.42326,300.20047,249.28957,0.00875
63.00000,5.44814,301.50061,250.36922,0.00879
63.30000,5.47316,302.68243,251.35062,0.00883
63.60000,5.49827,304.08099,252.51199,0.00887
63.90000,5.52314,305.49252,253.68414,0.00891
64.20000,5.54817,306.47729,254.50191,0.00895
64.50000,5.57319,307.64557,255.47205,0.00899
64.80000,5.59810,309.41129,256.93832,0.00903
65.10000,5.62317,310.44034,257.79285,0.00907
65.40000,5.64823,311.87613,258.98514,0.00911
65.70000,5.67309,313.34991,260.20898,0.00915
66.00000,5.69816,313.97833,260.73083,0.00919
66.30000,5.72321,315.76794,262.21695,0.00923
66.60000,5.74813,316.89413,263.15216,0.00927
66.90000,5.77314,317.97183,264.04709,0.00931
67.20000,5.79818,319.52664,265.33823,0.00935
67.50000,5.82318,320.51172,266.15622,0.00939
67.80000,5.84818,322.33691,267.67191,0.00943
68.10000,5.87318,323.07794,268.28726,0.00947
68.40000,5.89813,324.42758,269.40799,0.00951
68.70000,5.92318,325.61566,270.39459,0.00955
69.00000,5.94822,326.72253,271.31375,0.00959
69.30000,5.97315,328.20422,272.54416,0.00963
69.60000,5.99818,329.43094,273.56284,0.00967
69.90000,6.02323,330.82150,274.71759,0.00971
70.20000,6.04818,331.78632,275.51877,0.00975
70.50000,6.07320,333.37875,276.84116,0.00979
70.80000,6.09813,334.16333,277.49268,0.00984
71.10000,6.12308,335.78461,278.83899,0.00988
71.40000,6.14818,336.84018,279.71555,0.00992
71.70000,6.17311,337.92291,280.61465,0.00996
72.00000,6.19808,339.61581,282.02048,0.01000
72.30000,6.22323,340.39029,282.66360,0.01004
72.60000,6.24816,342.18103,284.15067,0.01008
72.90000,6.27316,343.04901,284.87143,0.01012
73.20000,6.29824,344.40244,285.99533,0.01016
73.50000,6.32311,345.37109,286.79971,0.01020
73.80000,6.34820,346.74771,287.94287,0.01024
74.10000,6.37324,348.08871,289.05646,0.01028
74.40000,6.39811,349.44479,290.18256,0.01032
74.70000,6.42318,350.43484,291.00470,0.01036
75.00000,6.44825,351.74420,292.09201,0.01040
75.30000,6.47316,352.75726,292.93326,0.01044
75.60000,6.49818,353.98111,293.94955,0.01048
75.90000,6.52319,355.28421,295.03168,0.01052
76.20000,6.54815,356.55276,296.08508,0.01056
76.50000,6.57322,357.54385,296.90811,0.01060
76.80000,6.59818,358.86517,298.00534,0.01064
77.10000,6.62316,360.48703,299.35214,0.01068
77.40000,6.64819,361.54047,300.22693,0.01072
77.70000,6.67316,362.78528,301.26062,0.01076
78.00000,6.69814,363.85651,302.15018,0.01080
78.30000,6.72311,365.22400,303.28577,0.01084
78.60000,6.74811,366.22815,304.11963,0.01088
78.90000,6.77316,367.53189,305.20227,0.01092
79.20000,6.79819,368.86728,306.31119,0.01096
79.50000,6.82314,369.76633,307.05777,0.01100
79.80000,6.84818,371.03906,308.11465,0.01104
80.10000,6.87324,371.96158,308.88074,0.01109
80.40000,6.89820,373.66937,310.29889,0.01113
80.70000,6.92316,374.45978,310.95526,0.01117
81.00000,6.94820,375.90247,312.15329,0.01121
81.30000,6.97315,377.18903,313.22165,0.01125
81.60000,6.99817,378.58545,314.38126,0.01129
81.90000,7.02324,379.40237,315.05963,0.01133
82.20000,7.04811,380.72946,316.16165,0.01137
82.50000,7.07319,382.10379,317.30292,0.01141
82.80000,7.09825,382.95425,318.00916,0.01145
83.10000,7.12313,384.32187,319.14484,0.01149
83.40000,7.14817,385.65115,320.24869,0.01153
83.70000,7.17326,386.55731,321.00116,0.01157
84.00000,7.19813,387.79230,322.02670,0.01161
84.30000,7.22319,388.94708,322.98566,0.01165
84.60000,7.24821,389.97992,323.84335,0.01169
84.90000,7.27312,391.16159,324.82462,0.01173
85.20000,7.29820,392.44992,325.89444,0.01177
85.50000,7.32321,393.76871,326.98959,0.01181
85.80000,7.34811,394.85156,327.88879,0.01185
86.10000,7.37319,396.19650,329.00565,0.01189
86.40000,7.39820,397.13354,329.78378,0.01193
86.70000,7.42318,398.70444,331.08826,0.01197
87.00000,7.44819,399.49149,331.74185,0.01201
87.30000,7.47316,400.59573,332.65881,0.01205
87.60000,7.49819,402.11890,333.92368,0.01209
87.90000,7.52323,403.14456,334.77539,0.01213
88.20000,7.54817,403.85989,335.36942,0.01217
88.50000,7.57316,405.30878,336.57257,0.01221
88.80000,7.59820,406.43796,337.51025,0.01225
89.10000,7.62318,407.72766,338.58124,0.01229
89.40000,7.64818,408.66431,339.35904,0.01233
89.70000,7.67318,410.01086,340.47723,0.01238
90.00000,7.69819,411.10342,341.38452,0.01242
90.30000,7.72322,412.32425,342.39832,0.01246
90.60000,7.74823,413.67123,343.51685,0.01250
90.90000,7.77317,414.66119,344.33893,0.01254
91.20000,7.79816,415.90033,345.36792,0.01258
91.50000,7.82321,416.88535,346.18588,0.01262
91.80000,7.84813,418.03705,347.14227,0.01266
92.10000,7.87315,419.14682,348.06384,0.01270
92.40000,7.89819,420.61337,349.28168,0.01274
92.70000,7.92312,421.74298,350.21973,0.01278
93.00000,7.94821,422.63107,350.95718,0.01282
93.30000,7.97322,423.61621,351.77527,0.01286
93.60000,7.99810,424.64932,352.63318,0.01290
93.90000,8.02321,426.25711,353.96829,0.01294
94.20000,8.04822,427.38461,354.90457,0.01298
94.50000,8.07312,428.35989,355.71448,0.01302
94.80000,8.09820,429.65390,356.78903,0.01306
95.10000,8.12319,430.52704,357.51410,0.01310
95.40000,8.14817,431.82773,358.59418,0.01314
95.70000,8.17325,433.05109,359.61008,0.01318
96.00000,8.19815,433.99313,360.39236,0.01322
96.30000,8.22313,435.01135,361.23792,0.01326
96.60000,8.24823,436.35611,362.35461,0.01330
96.90000,8.27318,437.58951,363.37885,0.01334
97.20000,8.29818,438.50009,364.13498,0.01338
97.50000,8.32322,439.80783,365.22095,0.01342
97.80000,8.34818,440.90530,366.13229,0.01346
98.10000,8.37321,442.08716,367.11374,0.01350
98.40000,8.39817,442.92221,367.80716,0.01354
98.70000,8.42310,444.57074,369.17612,0.01358
99.00000,8.44817,445.38101,369.84897,0.01363
99.30000,8.47320,446.42987,370.71997,0.01367
99.60000,8.49813,447.48645,371.59735,0.01371
99.90000,8.52317,448.71399,372.61673,0.01375
100.20000,8.54821,449.70660,373.44098,0.01379
100.50000,8.57319,451.00992,374.52328,0.01383
100.80000,8.59822,452.16516,375.48260,0.01387
101.10000,8.62321,453.19547,376.33817,0.01391
101.40000,8.64815,454.16919,377.14676,0.01395
101.70000,8.67322,455.63202,378.36151,0.01399
102.00000,8.69826,456.55322,379.12650,0.01403
102.30000,8.72311,457.54651,379.95132,0.01407
102.60000,8.74819,458.98645,381.14706,0.01411
102.90000,8.77324,459.92844,381.92932,0.01415
103.20000,8.79815,460.78156,382.63776,0.01419
103.50000,8.82321,461.97498,383.62878,0.01423
103.80000,8.84819,463.26807,384.70258,0.01427
104.10000,8.87312,464.35376,385.60416,0.01431
104.40000,8.89822,465.69391,386.71701,0.01435
104.70000,8.92318,466.44958,387.34454,0.01439
105.00000,8.94809,467.70581,388.38773,0.01443
105.30000,8.97321,469.10544,389.54999,0.01447
105.60000,8.99820,469.83151,390.15292,0.01451
105.90000,9.02314,471.09256,391.20010,0.01455
106.20000,9.04820,471.94901,391.91132,0.01459
106.50000,9.07316,473.15692,392.91437,0.01463
106.80000,9.09820,473.97342,393.59241,0.01467
107.10000,9.12323,475.26532,394.66522,0.01471
107.40000,9.14815,476.34802,395.56430,0.01475
107.70000,9.17321,477.41934,396.45395,0.01479
108.00000,9.19822,478.23959,397.13507,0.01483
108.30000,9.22319,479.36099,398.06631,0.01488
108.60000,9.24823,480.76706,399.23392,0.01492
108.90000,9.27320,481.75006,400.05020,0.01496
109.20000,9.29818,482.89450,401.00058,0.01500
109.50000,9.32324,483.83597,401.78238,0.01504
109.80000,9.34818,485.25662,402.96210,0.01508
110.10000,9.37316,486.25385,403.79019,0.01512
110.40000,9.39822,487.18414,404.56271,0.01516
110.70000,9.42321,488.15515,405.36905,0.01520
111.00000,9.44814,489.52530,406.50684,0.01524
111.30000,9.47318,490.37128,407.20935,0.01528
111.60000,9.49816,491.36639,408.03571,0.01532
111.90000,9.52314,492.72287,409.16214,0.01536
112.20000,9.54819,493.80496,410.06073,0.01540
112.50000,9.57316,494.45511,410.60062,0.01544
112.80000,9.59810,495.87137,411.77670,0.01548
113.10000,9.62322,496.84027,412.58127,0.01552
113.40000,9.64821,498.04633,413.58279,0.01556
113.70000,9.67312,499.18176,414.52567,0.01560
114.00000,9.69821,500.15231,415.33163,0.01564
114.30000,9.72321,501.26611,416.25653,0.01568
114.60000,9.74818,502.16461,417.00266,0.01572
114.90000,9.77324,503.08630,417.76804,0.01576
115.20000,9.79819,504.57681,419.00577,0.01580
115.50000,9.82319,505.56747,419.82843,0.01584
115.80000,9.84829,506.61679,420.69980,0.01588
116.10000,9.87317,507.58466,421.50351,0.01592
116.40000,9.89814,508.41965,422.19690,0.01596
116.70000,9.92322,509.53818,423.12576,0.01600
117.00000,9.94813,510.52756,423.94733,0.01604
117.30000,9.97318,511.74631,424.95941,0.01608
117.60000,9.99820,512.78656,425.82324,0.01613
117.90000,10.02314,513.92969,426.77249,0.01617
118.20000,10.04822,515.10321,427.74701,0.01621
118.50000,10.07318,515.97546,428.47134,0.01625
118.80000,10.09811,516.85663,429.20306,0.01629
119.10000,10.12317,518.12170,430.25360,0.01633
119.40000,10.14816,519.13898,431.09836,0.01637
119.70000,10.17313,520.27594,432.04251,0.01641
120.00000,10.19819,521.19049,432.80194,0.01645
120.30000,10.22315,522.08838,433.54758,0.01649
120.60000,10.24816,523.36249,434.60559,0.01653
120.90000,10.27323,524.34009,435.41742,0.01657
121.20000,10.29818,525.50189,436.38217,0.01661
121.50000,10.32314,526.62079,437.31131,0.01665
121.80000,10.34823,527.58386,438.11108,0.01669
122.10000,10.37321,528.47394,438.85019,0.01673
122.40000,10.39815,529.73804,439.89993,0.01677
122.70000,10.42321,530.30444,440.37027,0.01681
123.00000,10.44819,531.37708,441.26099,0.01685
123.30000,10.47317,532.54230,442.22861,0.01689
123.60000,10.49821,533.94293,443.39169,0.01693
123.90000,10.52317,534.54785,443.89404,0.01697
124.20000,10.54814,535.59314,444.76205,0.01701
124.50000,10.57321,536.97308,445.90799,0.01705
124.80000,10.59818,537.53345,446.37332,0.01709
125.10000,10.62312,538.77509,447.40439,0.01713
125.40000,10.64819,539.70789,448.17899,0.01717
125.70000,10.67315,541.01105,449.26114,0.01721
126.00000,10.69818,541.75153,449.87604,0.01725
126.30000,10.72318,542.87396,450.80814,0.01729
126.60000,10.74811,543.61938,451.42712,0.01733
126.90000,10.77317,544.95056,452.53256,0.01737
127.20000,10.79819,545.75684,453.20209,0.01742
127.50000,10.82312,547.03662,454.26483,0.01746
127.80000,10.84818,547.81744,454.91324,0.01750
128.10000,10.87317,548.76569,455.70068,0.01754
128.40000,10.89816,549.87476,456.62167,0.01758
128.70000,10.92326,550.87610,457.45319,0.01762
129.00000,10.94817,552.01178,458.39627,0.01766
129.30000,10.97315,553.11841,459.31522,0.01770
129.60000,10.99827,553.90942,459.97208,0.01774
129.90000,11.02316,555.09235,460.95441,0.01778
130.20000,11.04811,555.86938,461.59967,0.01782
130.50000,11.07321,556.62103,462.22385,0.01786
130.80000,11.09814,558.04352,463.40509,0.01790
131.10000,11.12316,558.84589,464.07138,0.01794
131.40000,11.14820,559.95813,464.99500,0.01798
131.70000,11.17311,560.88739,465.76666,0.01802
132.00000,11.19814,561.66821,466.41507,0.01806
132.30000,11.22323,563.14252,467.63934,0.01810
132.60000,11.24812,563.98584,468.33966,0.01814
132.90000,11.27312,564.83667,469.04617,0.01818
133.20000,11.29822,566.05548,470.05829,0.01822
133.50000,11.32319,566.91565,470.77258,0.01826
133.80000,11.34813,568.07715,471.73712,0.01830
134.10000,11.37319,568.60315,472.17392,0.01834
134.40000,11.39817,569.76410,473.13797,0.01838
134.70000,11.42318,570.69977,473.91498,0.01842
135.00000,11.44824,571.95709,474.95905,0.01846
135.30000,11.47314,572.46234,475.37863,0.01850
135.60000,11.49819,573.57336,476.30124,0.01854
135.90000,11.52327,574.80743,477.32602,0.01858
136.20000,11.54817,575.41492,477.83047,0.01862
136.50000,11.57316,576.57361,478.79266,0.01867
136.80000,11.59815,577.76105,479.77872,0.01871
137.10000,11.62311,578.48499,480.37988,0.01875
137.40000,11.64816,579.54224,481.25784,0.01879
137.70000,11.67312,580.38971,481.96158,0.01883
138.00000,11.69808,581.46222,482.85220,0.01887
138.30000,11.72324,582.61780,483.81183,0.01891
138.60000,11.74817,583.11584,484.22540,0.01895
138.90000,11.77313,584.38672,485.28076,0.01899
139.20000,11.79822,584.96295,485.75925,0.01903
139.50000,11.82314,586.20752,486.79276,0.01907
139.80000,11.84816,587.20593,487.62186,0.01911
140.10000,11.87323,587.87402,488.17664,0.01915
140.40000,11.89813,589.07312,489.17239,0.01919
140.70000,11.92316,590.00543,489.94659,0.01923
141.00000,11.94825,590.63519,490.46954,0.01927
141.30000,11.97318,591.94208,491.55481,0.01931
141.60000,11.99816,592.86279,492.31937,0.01935
141.90000,12.02322,593.72980,493.03934,0.01939
142.20000,12.04817,594.56696,493.73453,0.01943
142.50000,12.07320,595.75397,494.72021,0.01947
142.80000,12.09816,596.50323,495.34244,0.01951
143.10000,12.12313,597.55573,496.21643,0.01955
143.40000,12.14815,598.72479,497.18723,0.01959
143.70000,12.17319,599.40631,497.75317,0.01963
144.00000,12.19812,600.48273,498.64703,0.01967
144.30000,12.22310,601.24811,499.28262,0.01971
144.60000,12.24814,602.04388,499.94345,0.01975
144.90000,12.27315,603.13983,500.85352,0.01979
145.20000,12.29814,604.22675,501.75610,0.01983
145.50000,12.32317,604.98438,502.38525,0.01987
145.80000,12.34816,605.96521,503.19974,0.01992
146.10000,12.37322,606.80292,503.89539,0.01996
146.40000,12.39820,607.85797,504.77151,0.02000
146.70000,12.42314,608.65796,505.43582,0.02004
147.00000,12.44818,609.81470,506.39639,0.02008
147.30000,12.47317,610.59467,507.04410,0.02012
147.60000,12.49814,611.42969,507.73752,0.02016
147.90000,12.52322,612.46185,508.59464,0.02020
148.20000,12.54814,613.50287,509.45911,0.02024
148.50000,12.57317,614.32489,510.14172,0.02028
148.80000,12.59828,615.44098,511.06851,0.02032
149.10000,12.62313,615.96490,511.50360,0.02036
149.40000,12.64814,617.15009,512.48779,0.02040
149.70000,12.67324,618.05933,513.24280,0.02044
150.00000,12.69813,619.11615,514.12042,0.02048
150.30000,12.72316,619.59167,514.51532,0.02052
150.60000,12.74818,620.80920,515.52637,0.02056
150.90000,12.77309,621.63556,516.21259,0.02060
151.20000,12.79820,622.61859,517.02887,0.02064
151.50000,12.82322,623.29877,517.59369,0.02068
151.80000,12.84808,624.50250,518.59332,0.02072
152.10000,12.87318,625.08356,519.07581,0.02076
152.40000,12.89821,625.89209,519.74725,0.02080
152.70000,12.92314,626.85895,520.55011,0.02084
153.00000,12.94814,627.83844,521.36353,0.02088
153.30000,12.97319,628.71954,522.09515,0.02092
153.60000,12.99817,629.29022,522.56909,0.02096
153.90000,13.02318,630.29327,523.40204,0.02100
154.20000,13.04818,631.39111,524.31366,0.02104
154.50000,13.07314,632.47510,525.21381,0.02108
154.80000,13.09818,633.26111,525.86652,0.02112
155.10000,13.12320,634.07043,526.53864,0.02117
155.40000,13.14816,634.86316,527.19690,0.02121
155.70000,13.17317,635.90894,528.06531,0.02125
156.00000,13.19820,636.58997,528.63086,0.02129
156.30000,13.22320,637.41870,529.31903,0.02133
156.60000,13.24822,638.34705,530.08997,0.02137
156.90000,13.27316,639.51282,531.05804,0.02141
157.20000,13.29812,640.16150,531.59668,0.02145
157.50000,13.32322,641.40826,532.63202,0.02149
157.80000,13.34811,642.05042,533.16528,0.02153
158.10000,13.37311,642.95837,533.91925,0.02157
158.40000,13.39822,643.65082,534.49426,0.02161
158.70000,13.42314,644.56830,535.25616,0.02165
159.00000,13.44818,645.52765,536.05280,0.02169
159.30000,13.47323,646.58630,536.93195,0.02173
159.60000,13.49810,647.19916,537.44086,0.02177
159.90000,13.52318,647.75146,537.89948,0.02181
160.20000,13.54823,649.07263,538.99658,0.02185
160.50000,13.57310,649.70892,539.52496,0.02189
160.80000,13.59817,650.73175,540.37433,0.02193
161.10000,13.62324,651.51959,541.02856,0.02197
161.40000,13.64816,652.35077,541.71881,0.02201
161.70000,13.67318,652.86041,542.14203,0.02205
162.00000,13.69819,654.28253,543.32294,0.02209
162.30000,13.72316,654.99078,543.91107,0.02213
162.60000,13.74822,655.93524,544.69537,0.02217
162.90000,13.77318,656.95752,545.54431,0.02221
163.20000,13.79816,657.36328,545.88123,0.02225
163.50000,13.82322,658.27850,546.64124,0.02229
163.80000,13.84818,659.22577,547.42786,0.02233
164.10000,13.87316,660.06561,548.12531,0.02237
164.40000,13.89814,660.82623,548.75690,0.02241
164.70000,13.92313,661.96216,549.70020,0.02246
165.00000,13.94817,662.55487,550.19238,0.02250
165.30000,13.97319,663.60681,551.06592,0.02254
165.60000,13.99814,664.47467,551.78662,0.02258
165.90000,14.02317,665.14447,552.34283,0.02262
166.20000,14.04823,665.98486,553.04071,0.02266
166.50000,14.07319,666.66833,553.60828,0.02270
166.80000,14.09818,667.73438,554.49353,0.02274
167.10000,14.12320,668.55206,555.17255,0.02278
167.40000,14.14814,669.36670,555.84900,0.02282
167.70000,14.17318,670.31482,556.63635,0.02286
168.00000,14.19823,671.08289,557.27411,0.02290
168.30000,14.22311,671.88812,557.94281,0.02294
168.60000,14.24817,672.49121,558.44360,0.02298
168.90000,14.27326,673.65509,559.41010,0.02302
169.20000,14.29813,674.04883,559.73706,0.02306
169.50000,14.32318,675.16956,560.66772,0.02310
169.80000,14.34824,676.03662,561.38776,0.02314
170.10000,14.37311,676.84528,562.05927,0.02318
170.40000,14.39819,677.63831,562.71783,0.02322
170.70000,14.42316,678.62787,563.53955,0.02326
171.00000,14.44808,679.22150,564.03253,0.02330
171.30000,14.47320,680.23303,564.87250,0.02334
171.60000,14.49821,680.83728,565.37427,0.02338
171.90000,14.52310,681.77057,566.14929,0.02342
172.20000,14.54821,682.62665,566.86017,0.02346
172.50000,14.57319,683.49542,567.58167,0.02350
172.80000,14.59820,684.18732,568.15619,0.02354
173.10000,14.62322,685.31055,569.08893,0.02358
173.40000,14.64817,685.73865,569.44446,0.02362
173.70000,14.67319,686.57953,570.14270,0.02366
174.00000,14.69824,687.56165,570.95825,0.02371
174.30000,14.72317,688.08478,571.39270,0.02375
174.60000,14.74817,689.13605,572.26569,0.02379
174.90000,14.77319,689.66913,572.70837,0.02383
175.20000,14.79819,690.74420,573.60107,0.02387
175.50000,14.82318,691.47662,574.20929,0.02391
175.80000,14.84820,692.22839,574.83356,0.02395
176.10000,14.87316,692.83344,575.33600,0.02399
176.40000,14.89820,693.88239,576.20709,0.02403
176.70000,14.92323,694.54834,576.76007,0.02407
177.00000,14.94815,695.47192,577.52704,0.02411
177.30000,14.97314,696.16974,578.10651,0.02415
177.60000,14.99819,696.95697,578.76025,0.02419
177.90000,15.02314,697.77173,579.43683,0.02423
178.20000,15.04815,698.78461,580.27795,0.02427
178.50000,15.07318,699.40607,580.79401,0.02431
178.80000,15.09813,700.32336,581.55573,0.02435
179.10000,15.12323,701.08984,582.19220,0.02439
179.40000,15.14823,701.67474,582.67792,0.02443
179.70000,15.17311,702.52808,583.38654,0.02447
180.00000,15.19823,703.55219,584.23700,0.02451
180.30000,15.22324,704.03369,584.63684,0.02455
180.60000,15.24814,705.03558,585.46881,0.02459
180.90000,15.27323,705.92633,586.20850,0.02463
181.20000,15.29818,706.24414,586.47241,0.02467
181.50000,15.32317,707.39728,587.42999,0.02471
181.80000,15.34826,708.07013,587.98871,0.02475
182.10000,15.37317,708.70227,588.51367,0.02479
182.40000,15.39814,709.79333,589.41968,0.02483
182.70000,15.42323,710.26849,589.81427,0.02487
183.00000,15.44819,711.14972,590.54602,0.02491
183.30000,15.47318,711.65137,590.96265,0.02496
183.60000,15.49822,712.82983,591.94122,0.02500
183.90000,15.52317,713.57196,592.55750,0.02504
184.20000,15.54821,714.37445,593.22388,0.02508
184.50000,15.57319,714.89343,593.65485,0.02512
184.80000,15.59812,715.85522,594.45355,0.02516
185.10000,15.62317,716.58868,595.06262,0.02520
185.40000,15.64819,717.32269,595.67212,0.02524
185.70000,15.67312,717.92535,596.17261,0.02528
186.00000,15.69818,718.67352,596.79388,0.02532
186.30000,15.72320,719.38947,597.38843,0.02536
186.60000,15.74818,720.38434,598.21460,0.02540
186.90000,15.77325,721.22308,598.91107,0.02544
187.20000,15.79818,721.78741,599.37970,0.02548
187.50000,15.82315,722.80450,600.22430,0.02552
187.80000,15.84822,723.33472,600.66461,0.02556
188.10000,15.87323,724.21088,601.39215,0.02560
188.40000,15.89812,724.67212,601.77521,0.02564
188.70000,15.92320,725.45618,602.42627,0.02568
189.00000,15.94824,726.41644,603.22369,0.02572
189.30000,15.97314,727.21124,603.88373,0.02576
189.60000,15.99823,727.93622,604.48572,0.02580
189.90000,16.02319,728.56061,605.00421,0.02584
190.20000,16.04812,729.05237,605.41260,0.02588
190.50000,16.07323,730.33002,606.47357,0.02592
190.80000,16.09820,730.40820,606.53851,0.02596
191.10000,16.12310,731.71600,607.62451,0.02600
191.40000,16.14822,732.40918,608.20013,0.02604
191.70000,16.17320,733.00879,608.69806,0.02608
192.00000,16.19813,733.69659,609.26923,0.02612
192.30000,16.22320,734.52148,609.95422,0.02616
192.60000,16.24813,735.16010,610.48450,0.02620
192.90000,16.27318,735.84723,611.05511,0.02625
193.20000,16.29821,736.54425,611.63391,0.02629
193.50000,16.32313,737.36383,612.31451,0.02633
193.80000,16.34821,738.08136,612.91034,0.02637
194.10000,16.37321,738.70258,613.42621,0.02641
194.40000,16.39816,739.55566,614.13464,0.02645
194.70000,16.42324,740.31183,614.76257,0.02649
195.00000,16.44819,741.21356,615.51135,0.02653
195.30000,16.47317,741.86847,616.05524,0.02657
195.60000,16.49826,742.47589,616.55963,0.02661
195.90000,16.52318,743.43195,617.35352,0.02665
196.20000,16.54815,744.30554,618.07898,0.02669
196.50000,16.57322,744.92822,618.59607,0.02673
196.80000,16.59822,745.48230,619.05615,0.02677
197.10000,16.62316,745.99811,619.48450,0.02681
197.40000,16.64819,746.81012,620.15881,0.02685
197.70000,16.67314,747.53857,620.76373,0.02689
198.00000,16.69813,748.65167,621.68805,0.02693
198.30000,16.72320,749.08984,622.05194,0.02697
198.60000,16.74816,749.59540,622.47174,0.02701
198.90000,16.77311,750.20581,622.97864,0.02705
199.20000,16.79823,751.18512,623.79187,0.02709
199.50000,16.82321,751.71088,624.22845,0.02713
199.80000,16.84811,752.55194,624.92688,0.02717
200.10000,16.87320,753.59155,625.79016,0.02721
200.40000,16.89820,753.90155,626.04761,0.02725
200.70000,16.92319,754.78125,626.77814,0.02729
201.00000,16.94826,755.52155,627.39288,0.02733
201.30000,16.97317,756.27118,628.01538,0.02737
201.60000,16.99821,756.68042,628.35522,0.02741
201.90000,17.02328,757.65881,629.16766,0.02746
202.20000,17.04816,758.15179,629.57703,0.02750
202.50000,17.07318,758.86517,630.16943,0.02754
202.80000,17.09820,759.42682,630.63586,0.02758
203.10000,17.12312,760.68066,631.67706,0.02762
203.40000,17.14819,760.98822,631.93243,0.02766
203.70000,17.17317,761.99957,632.77228,0.02770
204.00000,17.19812,762.73615,633.38397,0.02774
204.30000,17.22322,763.09436,633.68140,0.02778
204.60000,17.24819,764.15009,634.55811,0.02782
204.90000,17.27312,764.74451,635.05170,0.02786
205.20000,17.29818,765.45294,635.64001,0.02790
205.50000,17.32318,766.03723,636.12518,0.02794
205.80000,17.34815,766.79669,636.75586,0.02798
206.10000,17.37320,767.69965,637.50568,0.02802
206.40000,17.39814,768.13458,637.86688,0.02806
206.70000,17.42317,768.88031,638.48615,0.02810
207.00000,17.44826,769.41705,638.93182,0.02814
207.30000,17.47318,770.17719,639.56305,0.02818
207.60000,17.49816,770.63141,639.94025,0.02822
207.90000,17.52325,771.61823,640.75970,0.02826
208.20000,17.54821,772.56476,641.54572,0.02830
208.50000,17.57316,773.48676,642.31134,0.02834
208.80000,17.59821,773.85730,642.61908,0.02838
209.10000,17.62316,774.50024,643.15295,0.02842
209.40000,17.64816,775.15674,643.69812,0.02846
209.70000,17.67320,776.01868,644.41388,0.02850
210.00000,17.69816,776.70752,644.98590,0.02854
210.30000,17.72311,777.32581,645.49933,0.02858
210.60000,17.74821,778.07953,646.12524,0.02862
210.90000,17.77315,779.18109,647.03998,0.02866
211.20000,17.79813,779.47754,647.28619,0.02870
211.50000,17.82318,780.01917,647.73596,0.02875
211.80000,17.84815,780.95142,648.51007,0.02879
212.10000,17.87319,781.73651,649.16205,0.02883
212.40000,17.89819,782.30627,649.63519,0.02887
212.70000,17.92310,782.83551,650.07465,0.02891
213.00000,17.94815,783.83569,650.90521,0.02895
213.30000,17.97319,784.55743,651.50458,0.02899
213.60000,17.99812,784.99133,651.86487,0.02903
213.90000,18.02319,785.99261,652.69635,0.02907
214.20000,18.04816,786.40192,653.03625,0.02911
214.50000,18.07317,787.39563,653.86145,0.02915
214.80000,18.09827,788.01733,654.37769,0.02919
215.10000,18.12315,788.59283,654.85559,0.02923
215.40000,18.14814,789.40063,655.52643,0.02927
215.70000,18.17326,789.71185,655.78485,0.02931
216.00000,18.19814,790.61774,656.53711,0.02935
216.30000,18.22312,791.36157,657.15479,0.02939
216.60000,18.24820,792.09619,657.76483,0.02943
216.90000,18.27312,792.29065,657.92633,0.02947
217.20000,18.29817,793.33331,658.79218,0.02951
217.50000,18.32321,794.15161,659.47168,0.02955
217.80000,18.34809,794.74481,659.96429,0.02959
218.10000,18.37315,795.32306,660.44446,0.02963
218.40000,18.39823,796.17035,661.14807,0.02967
218.70000,18.42313,796.51190,661.43170,0.02971
219.00000,18.44812,797.22864,662.02686,0.02975
219.30000,18.47320,798.11194,662.76038,0.02979
219.60000,18.49819,798.70282,663.25104,0.02983
219.90000,18.52314,799.01642,663.51147,0.02987
220.20000,18.54819,799.86212,664.21375,0.02991
220.50000,18.57315,800.60260,664.82861,0.02995
220.80000,18.59816,800.92108,665.09314,0.03000
221.10000,18.62324,801.83508,665.85211,0.03004
221.40000,18.64812,802.24921,666.19598,0.03008
221.70000,18.67318,802.97290,666.79694,0.03012
222.00000,18.69824,803.41907,667.16748,0.03016
222.30000,18.72319,804.17377,667.79419,0.03020
222.60000,18.74820,805.62457,668.99896,0.03024
222.90000,18.77315,739.50970,614.09650,0.03028
223.20000,18.79812,709.23145,588.95306,0.03032
223.50000,18.82318,700.57605,581.76556,0.03036
223.80000,18.84813,695.22150,577.31909,0.03040
224.10000,18.87309,690.24725,573.18842,0.03044
224.40000,18.89824,686.22943,569.85199,0.03048
224.70000,18.92317,672.27222,558.26178,0.03052
225.00000,18.94815,659.31549,547.50238,0.03056
225.30000,18.97320,633.80920,526.32172,0.03060
225.50200,18.99003,618.37128,513.50189,0.03063