File: Specimen_RawData_3.csv
Break (Cursor) : Flexure stress at Break (Cursor),"748.03339",MPa
Modulus (Automatic Young's) : Modulus (Automatic Young's),"29926.08830",MPa
Specimen properties : Support span,"125.00000",mm
Specimen properties : Thickness,"4.14000",mm
Specimen properties : Width,"12.86000",mm
Specimen properties : Specimen label,"3A"

Time,Extension,Load,Flexure stress,Flexure strain (Extension)
(s),(mm),(N),(MPa),(mm/mm)
"0.00000","0.23270","10.02879","8.53116","0.00037"
"0.40000","0.26418","11.63647","9.89876","0.00042"
"0.80000","0.29760","13.26112","11.28079","0.00047"
"1.20000","0.33087","15.52024","13.20255","0.00053"
"1.60000","0.36425","17.44139","14.83682","0.00058"
"2.00000","0.39754","19.40322","16.50568","0.00063"
"2.40000","0.43093","21.02440","17.88476","0.00069"
"2.80000","0.46418","22.72674","19.33289","0.00074"
"3.20000","0.49756","24.62706","20.94943","0.00079"
"3.60000","0.53085","26.46785","22.51533","0.00084"
"4.00000","0.56424","28.45191","24.20310","0.00090"
"4.40000","0.59757","30.45348","25.90577","0.00095"
"4.80000","0.63088","32.41652","27.57566","0.00100"
"5.20000","0.66421","34.21976","29.10962","0.00106"
"5.60000","0.69750","35.85689","30.50227","0.00111"
"6.00000","0.73093","37.97593","32.30487","0.00116"
"6.40000","0.76419","39.59871","33.68532","0.00121"
"6.80000","0.79762","41.35160","35.17644","0.00127"
"7.20000","0.83085","43.45255","36.96365","0.00132"
"7.60000","0.86425","45.54199","38.74107","0.00137"
"8.00000","0.89751","47.41933","40.33806","0.00143"
"8.40000","0.93091","49.14622","41.80708","0.00148"
"8.80000","0.96421","51.08927","43.45996","0.00153"
"9.20000","0.99761","53.07129","45.14599","0.00159"
"9.60000","1.03089","54.69685","46.52881","0.00164"
"10.00000","1.06420","56.76253","48.28601","0.00169"
"10.40000","1.09760","58.36554","49.64964","0.00174"
"10.80000","1.13085","60.26073","51.26181","0.00180"
"11.20000","1.16428","62.24743","52.95184","0.00185"
"11.60000","1.19757","64.03627","54.47355","0.00190"
"12.00000","1.23093","66.19482","56.30975","0.00196"
"12.40000","1.26424","68.15591","57.97798","0.00201"
"12.80000","1.29757","69.86426","59.43122","0.00206"
"13.20000","1.33090","71.86221","61.13082","0.00212"
"13.60000","1.36424","73.46483","62.49411","0.00217"
"14.00000","1.39760","75.75114","64.43900","0.00222"
"14.40000","1.43094","77.39617","65.83837","0.00227"
"14.80000","1.46423","79.42735","67.56622","0.00233"
"15.20000","1.49760","80.93266","68.84675","0.00238"
"15.60000","1.53090","83.15263","70.73521","0.00243"
"16.00000","1.56422","84.84773","72.17717","0.00249"
"16.40000","1.59767","86.55777","73.63184","0.00254"
"16.80000","1.63087","88.75283","75.49911","0.00259"
"17.20000","1.66431","90.61134","77.08009","0.00265"
"17.60000","1.69753","92.18393","78.41783","0.00270"
"18.00000","1.73094","94.26997","80.19236","0.00275"
"18.40000","1.76424","96.12159","81.76747","0.00280"
"18.80000","1.79761","97.61097","83.03443","0.00286"
"19.20000","1.83092","100.05865","85.11659","0.00291"
"19.60000","1.86424","101.31014","86.18120","0.00296"
"20.00000","1.89758","103.44081","87.99369","0.00302"
"20.40000","1.93091","105.41991","89.67725","0.00307"
"20.80000","1.96422","107.42995","91.38712","0.00312"
"21.20000","1.99758","108.85271","92.59742","0.00318"
"21.60000","2.03093","110.49696","93.99612","0.00323"
"22.00000","2.06423","112.61155","95.79493","0.00328"
"22.40000","2.09760","114.53717","97.43300","0.00333"
"22.80000","2.13082","116.36075","98.98425","0.00339"
"23.20000","2.16426","118.49171","100.79699","0.00344"
"23.60000","2.19755","120.08522","102.15254","0.00349"
"24.00000","2.23091","122.29465","104.03203","0.00355"
"24.40000","2.26419","123.76846","105.28574","0.00360"
"24.80000","2.29756","125.84359","107.05099","0.00365"
"25.20000","2.33088","127.31623","108.30372","0.00371"
"25.60000","2.36420","129.19127","109.89875","0.00376"
"26.00000","2.39759","131.18138","111.59167","0.00381"
"26.40000","2.43083","133.13765","113.25581","0.00386"
"26.80000","2.46429","134.80898","114.67755","0.00392"
"27.20000","2.49748","136.90665","116.46198","0.00397"
"27.60000","2.53092","138.58394","117.88879","0.00402"
"28.00000","2.56414","140.51569","119.53206","0.00408"
"28.40000","2.59761","142.45927","121.18541","0.00413"
"28.80000","2.63087","144.16681","122.63795","0.00418"
"29.20000","2.66422","145.97148","124.17313","0.00424"
"29.60000","2.69757","147.72980","125.66887","0.00429"
"30.00000","2.73083","149.72523","127.36633","0.00434"
"30.40000","2.76423","151.48053","128.85950","0.00439"
"30.80000","2.79757","153.16747","130.29451","0.00445"
"31.20000","2.83092","154.93024","131.79405","0.00450"
"31.60000","2.86420","156.98000","133.53770","0.00455"
"32.00000","2.89758","158.60577","134.92070","0.00461"
"32.40000","2.93085","160.72484","136.72333","0.00466"
"32.80000","2.96427","162.52077","138.25105","0.00471"
"33.20000","2.99752","164.22188","139.69814","0.00477"
"33.60000","3.03095","166.04903","141.25243","0.00482"
"34.00000","3.06422","167.83662","142.77309","0.00487"
"34.40000","3.09759","169.65019","144.31583","0.00492"
"34.80000","3.13087","171.38373","145.79048","0.00498"
"35.20000","3.16422","173.40096","147.50647","0.00503"
"35.60000","3.19762","175.28313","149.10757","0.00508"
"36.00000","3.23086","176.93484","150.51263","0.00514"
"36.40000","3.26430","178.66885","151.98770","0.00519"
"36.80000","3.29755","180.48679","153.53416","0.00524"
"37.20000","3.33095","182.39047","155.15356","0.00530"
"37.60000","3.36422","184.39455","156.85837","0.00535"
"38.00000","3.39762","186.01254","158.23474","0.00540"
"38.40000","3.43091","187.91476","159.85289","0.00545"
"38.80000","3.46426","189.40973","161.12462","0.00551"
"39.20000","3.49759","191.40872","162.82509","0.00556"
"39.60000","3.53088","193.15668","164.31201","0.00561"
"40.00000","3.56426","195.09467","165.96060","0.00567"
"40.40000","3.59756","196.68980","167.31754","0.00572"
"40.80000","3.63097","198.65459","168.98891","0.00577"
"41.20000","3.66422","200.20651","170.30908","0.00583"
"41.60000","3.69760","202.21637","172.01880","0.00588"
"42.00000","3.73081","203.89363","173.44559","0.00593"
"42.40000","3.76430","205.71323","174.99345","0.00598"
"42.80000","3.79757","207.64209","176.63428","0.00604"
"43.20000","3.83093","209.23111","177.98601","0.00609"
"43.60000","3.86424","211.34157","179.78131","0.00614"
"44.00000","3.89759","212.63361","180.88040","0.00620"
"44.40000","3.93088","214.77010","182.69785","0.00625"
"44.80000","3.96425","216.22420","183.93480","0.00630"
"45.20000","3.99756","218.20969","185.62379","0.00636"
"45.60000","4.03089","219.82535","186.99818","0.00641"
"46.00000","4.06430","221.96112","188.81500","0.00646"
"46.40000","4.09750","223.26810","189.92680","0.00651"
"46.80000","4.13094","225.07217","191.46149","0.00657"
"47.20000","4.16417","227.23503","193.30135","0.00662"
"47.60000","4.19758","228.85149","194.67642","0.00667"
"48.00000","4.23090","230.52917","196.10358","0.00673"
"48.40000","4.26423","232.29503","197.60573","0.00678"
"48.80000","4.29755","234.29517","199.30717","0.00683"
"49.20000","4.33084","235.89626","200.66917","0.00689"
"49.60000","4.36421","237.32207","201.88206","0.00694"
"50.00000","4.39754","239.10318","203.39719","0.00699"
"50.40000","4.43090","241.16864","205.15421","0.00704"
"50.80000","4.46425","242.89566","206.62334","0.00710"
"51.20000","4.49753","244.81458","208.25569","0.00715"
"51.60000","4.53087","246.29808","209.51765","0.00720"
"52.00000","4.56425","247.87558","210.85959","0.00726"
"52.40000","4.59750","249.57378","212.30418","0.00731"
"52.80000","4.63095","251.31236","213.78314","0.00736"
"53.20000","4.66421","253.34061","215.50850","0.00741"
"53.60000","4.69758","254.77254","216.72659","0.00747"
"54.00000","4.73085","256.56561","218.25191","0.00752"
"54.40000","4.76422","258.33185","219.75439","0.00757"
"54.80000","4.79756","260.14435","221.29622","0.00763"
"55.20000","4.83092","261.42966","222.38959","0.00768"
"55.60000","4.86426","263.49435","224.14597","0.00773"
"56.00000","4.89751","265.10794","225.51859","0.00779"
"56.40000","4.93094","266.97617","227.10782","0.00784"
"56.80000","4.96418","268.63257","228.51688","0.00789"
"57.20000","4.99759","270.18497","229.83745","0.00794"
"57.60000","5.03087","271.88141","231.28055","0.00800"
"58.00000","5.06433","273.86475","232.96771","0.00805"
"58.40000","5.09754","275.35385","234.23445","0.00810"
"58.80000","5.13093","277.28876","235.88040","0.00816"
"59.20000","5.16421","278.82407","237.18645","0.00821"
"59.60000","5.19759","280.77454","238.84564","0.00826"
"60.00000","5.23093","282.37698","240.20879","0.00832"
"60.40000","5.26427","283.68100","241.31807","0.00837"
"60.80000","5.29759","285.64032","242.98480","0.00842"
"61.20000","5.33092","287.30933","244.40457","0.00847"
"61.60000","5.36424","289.11310","245.93898","0.00853"
"62.00000","5.39755","290.79077","247.36612","0.00858"
"62.40000","5.43096","292.25998","248.61594","0.00863"
"62.80000","5.46423","294.03641","250.12708","0.00869"
"63.20000","5.49766","295.73761","251.57423","0.00874"
"63.60000","5.53087","297.34341","252.94025","0.00879"
"64.00000","5.56428","299.10638","254.43994","0.00885"
"64.40000","5.59753","300.41956","255.55701","0.00890"
"64.80000","5.63091","302.15771","257.03561","0.00895"
"65.20000","5.66430","304.14725","258.72803","0.00900"
"65.60000","5.69754","305.60370","259.96698","0.00906"
"66.00000","5.73097","307.31555","261.42322","0.00911"
"66.40000","5.76419","309.14639","262.98065","0.00916"
"66.80000","5.79760","310.57446","264.19547","0.00922"
"67.20000","5.83087","312.55905","265.88370","0.00927"
"67.60000","5.86427","313.86105","266.99124","0.00932"
"68.00000","5.89754","315.54745","268.42581","0.00938"
"68.40000","5.93094","317.11139","269.75620","0.00943"
"68.80000","5.96418","318.90063","271.27826","0.00948"
"69.20000","5.99756","320.41452","272.56607","0.00953"
"69.60000","6.03087","322.25497","274.13168","0.00959"
"70.00000","6.06423","323.89316","275.52524","0.00964"
"70.40000","6.09757","325.45892","276.85718","0.00969"
"70.80000","6.13087","327.25925","278.38864","0.00975"
"71.20000","6.16425","328.56998","279.50366","0.00980"
"71.60000","6.19747","330.69675","281.31284","0.00985"
"72.00000","6.23095","332.11346","282.51797","0.00991"
"72.40000","6.26415","333.39548","283.60855","0.00996"
"72.80000","6.29763","335.30511","285.23300","0.01001"
"73.20000","6.33083","337.05627","286.72266","0.01006"
"73.60000","6.36424","338.64935","288.07785","0.01012"
"74.00000","6.39751","340.05804","289.27618","0.01017"
"74.40000","6.43090","341.43289","290.44571","0.01022"
"74.80000","6.46422","343.28653","292.02252","0.01028"
"75.20000","6.49754","344.86243","293.36310","0.01033"
"75.60000","6.53092","346.46231","294.72406","0.01038"
"76.00000","6.56416","347.75366","295.82257","0.01044"
"76.40000","6.59758","349.82440","297.58408","0.01049"
"76.80000","6.63084","351.32364","298.85944","0.01054"
"77.20000","6.66428","352.96915","300.25922","0.01059"
"77.60000","6.69752","354.17145","301.28198","0.01065"
"78.00000","6.73092","356.05655","302.88556","0.01070"
"78.40000","6.76423","357.55219","304.15787","0.01075"
"78.80000","6.79754","359.34119","305.67969","0.01081"
"79.20000","6.83093","360.92297","307.02527","0.01086"
"79.60000","6.86417","362.35214","308.24103","0.01091"
"80.00000","6.89761","363.57190","309.27863","0.01097"
"80.40000","6.93093","365.32440","310.76944","0.01102"
"80.80000","6.96424","367.06021","312.24603","0.01107"
"81.20000","6.99753","368.52176","313.48932","0.01112"
"81.60000","7.03096","370.50995","315.18060","0.01118"
"82.00000","7.06419","371.86124","316.33011","0.01123"
"82.40000","7.09765","373.21521","317.48187","0.01128"
"82.80000","7.13087","374.77869","318.81189","0.01134"
"83.20000","7.16429","376.20087","320.02167","0.01139"
"83.60000","7.19753","377.83936","321.41550","0.01144"
"84.00000","7.23092","379.59445","322.90848","0.01150"
"84.40000","7.26427","381.21622","324.28806","0.01155"
"84.80000","7.29758","382.67358","325.52780","0.01160"
"85.20000","7.33095","384.04910","326.69791","0.01165"
"85.60000","7.36422","385.80881","328.19482","0.01171"
"86.00000","7.39761","387.35757","329.51233","0.01176"
"86.40000","7.43090","388.87912","330.80664","0.01181"
"86.80000","7.46426","390.18726","331.91943","0.01187"
"87.20000","7.49758","391.83432","333.32053","0.01192"
"87.60000","7.53095","393.46045","334.70383","0.01197"
"88.00000","7.56422","394.96417","335.98300","0.01203"
"88.40000","7.59758","396.24081","337.06900","0.01208"
"88.80000","7.63089","397.86948","338.45444","0.01213"
"89.20000","7.66424","399.48715","339.83057","0.01218"
"89.60000","7.69761","401.08896","341.19315","0.01224"
"90.00000","7.73090","402.67386","342.54138","0.01229"
"90.40000","7.76423","403.95331","343.62976","0.01234"
"90.80000","7.79755","405.47748","344.92633","0.01240"
"91.20000","7.83090","407.01837","346.23712","0.01245"
"91.60000","7.86419","408.52658","347.52011","0.01250"
"92.00000","7.89761","410.12650","348.88110","0.01256"
"92.40000","7.93085","411.86954","350.36383","0.01261"
"92.80000","7.96427","413.23990","351.52957","0.01266"
"93.20000","7.99750","414.63885","352.71960","0.01271"
"93.60000","8.03094","415.78378","353.69357","0.01277"
"94.00000","8.06416","417.52222","355.17239","0.01282"
"94.40000","8.09758","419.12918","356.53937","0.01287"
"94.80000","8.13093","420.47046","357.68036","0.01293"
"95.20000","8.16418","422.03616","359.01227","0.01298"
"95.60000","8.19756","423.60669","360.34824","0.01303"
"96.00000","8.23083","425.19922","361.70297","0.01309"
"96.40000","8.26425","426.44589","362.76346","0.01314"
"96.80000","8.29756","427.89603","363.99704","0.01319"
"97.20000","8.33091","429.45392","365.32230","0.01324"
"97.60000","8.36418","431.14484","366.76071","0.01330"
"98.00000","8.39755","432.58047","367.98196","0.01335"
"98.40000","8.43084","434.10681","369.28036","0.01340"
"98.80000","8.46424","435.37292","370.35739","0.01346"
"99.20000","8.49753","436.99173","371.73447","0.01351"
"99.60000","8.53095","437.98450","372.57898","0.01356"
"100.00000","8.56419","439.66025","374.00449","0.01362"
"100.40000","8.59758","441.37619","375.46417","0.01367"
"100.80000","8.63089","442.59058","376.49722","0.01372"
"101.20000","8.66418","444.11169","377.79117","0.01377"
"101.60000","8.69765","445.68924","379.13315","0.01383"
"102.00000","8.73083","446.72665","380.01562","0.01388"
"102.40000","8.76430","448.33249","381.38168","0.01393"
"102.80000","8.79753","449.75925","382.59537","0.01399"
"103.20000","8.83093","451.24503","383.85928","0.01404"
"103.60000","8.86422","452.79688","385.17938","0.01409"
"104.00000","8.89759","454.67917","386.78058","0.01415"
"104.40000","8.93092","455.69293","387.64294","0.01420"
"104.80000","8.96424","457.26715","388.98209","0.01425"
"105.20000","8.99761","458.51971","390.04761","0.01430"
"105.60000","9.03088","460.37097","391.62241","0.01436"
"106.00000","9.06424","461.61932","392.68436","0.01441"
"106.40000","9.09756","463.00909","393.86658","0.01446"
"106.80000","9.13103","464.34247","395.00082","0.01452"
"107.20000","9.16419","465.56302","396.03912","0.01457"
"107.60000","9.19763","467.12183","397.36514","0.01462"
"108.00000","9.23083","468.71194","398.71780","0.01467"
"108.40000","9.26428","470.25998","400.03467","0.01473"
"108.80000","9.29759","471.55853","401.13931","0.01478"
"109.20000","9.33094","472.94394","402.31781","0.01483"
"109.60000","9.36423","474.23596","403.41690","0.01489"
"110.00000","9.39761","475.89261","404.82614","0.01494"
"110.40000","9.43090","477.08371","405.83939","0.01499"
"110.80000","9.46423","478.66681","407.18607","0.01505"
"111.20000","9.49759","480.02219","408.33905","0.01510"
"111.60000","9.53088","481.26810","409.39890","0.01515"
"112.00000","9.56433","482.77405","410.67996","0.01520"
"112.40000","9.59751","484.22394","411.91333","0.01526"
"112.80000","9.63094","485.47433","412.97702","0.01531"
"113.20000","9.66416","487.12692","414.38281","0.01536"
"113.60000","9.69759","488.12360","415.23065","0.01542"
"114.00000","9.73093","489.82034","416.67401","0.01547"
"114.40000","9.76424","491.14374","417.79977","0.01552"
"114.80000","9.79759","492.60379","419.04181","0.01558"
"115.20000","9.83082","493.88165","420.12885","0.01563"
"115.60000","9.86427","495.41833","421.43604","0.01568"
"116.00000","9.89753","496.58160","422.42560","0.01573"
"116.40000","9.93093","498.02832","423.65628","0.01579"
"116.80000","9.96420","499.70273","425.08063","0.01584"
"117.20000","9.99760","500.67117","425.90445","0.01589"
"117.60000","10.03084","502.11581","427.13336","0.01595"
"118.00000","10.06425","503.57101","428.37128","0.01600"
"118.40000","10.09751","504.79330","429.41101","0.01605"
"118.80000","10.13091","506.11694","430.53699","0.01611"
"119.20000","10.16423","507.60965","431.80679","0.01616"
"119.60000","10.19756","509.21689","433.17401","0.01621"
"120.00000","10.23085","510.37021","434.15512","0.01626"
"120.40000","10.26418","511.55801","435.16553","0.01632"
"120.80000","10.29758","513.22693","436.58524","0.01637"
"121.20000","10.33089","514.45380","437.62888","0.01642"
"121.60000","10.36428","515.77405","438.75198","0.01648"
"122.00000","10.39752","516.98206","439.77960","0.01653"
"122.40000","10.43094","518.69232","441.23447","0.01658"
"122.80000","10.46418","520.15540","442.47903","0.01664"
"123.20000","10.49760","521.74957","443.83517","0.01669"
"123.60000","10.53086","522.64301","444.59518","0.01674"
"124.00000","10.56426","523.79614","445.57611","0.01679"
"124.40000","10.59759","525.17529","446.74930","0.01685"
"124.80000","10.63087","526.63104","447.98767","0.01690"
"125.20000","10.66424","527.94769","449.10770","0.01695"
"125.60000","10.69754","529.20911","450.18076","0.01701"
"126.00000","10.73094","530.28656","451.09729","0.01706"
"126.40000","10.76427","531.91650","452.48383","0.01711"
"126.80000","10.79758","533.02539","453.42712","0.01717"
"127.20000","10.83091","534.64038","454.80093","0.01722"
"127.60000","10.86424","535.82599","455.80951","0.01727"
"128.00000","10.89756","537.07410","456.87122","0.01732"
"128.40000","10.93093","538.20453","457.83286","0.01738"
"128.80000","10.96425","539.67151","459.08075","0.01743"
"129.20000","10.99766","541.15656","460.34406","0.01748"
"129.60000","11.03089","542.34430","461.35443","0.01754"
"130.00000","11.06426","543.69769","462.50571","0.01759"
"130.40000","11.09757","544.88696","463.51736","0.01764"
"130.80000","11.13089","546.13757","464.58124","0.01770"
"131.20000","11.16433","547.69409","465.90530","0.01775"
"131.60000","11.19752","549.34290","467.30789","0.01780"
"132.00000","11.23097","550.26544","468.09268","0.01785"
"132.40000","11.26420","551.80872","469.40549","0.01791"
"132.80000","11.29762","552.70929","470.17157","0.01796"
"133.20000","11.33088","554.10602","471.35971","0.01801"
"133.60000","11.36428","555.08295","472.19077","0.01807"
"134.00000","11.39757","556.73083","473.59256","0.01812"
"134.40000","11.43089","557.86133","474.55423","0.01817"
"134.80000","11.46423","559.36298","475.83163","0.01823"
"135.20000","11.49758","560.58716","476.87302","0.01828"
"135.60000","11.53087","561.82159","477.92313","0.01833"
"136.00000","11.56425","562.88092","478.82425","0.01838"
"136.40000","11.59757","564.39917","480.11578","0.01844"
"136.80000","11.63088","565.57812","481.11868","0.01849"
"137.20000","11.66426","566.56580","481.95886","0.01854"
"137.60000","11.69748","568.16052","483.31543","0.01860"
"138.00000","11.73093","569.29382","484.27948","0.01865"
"138.40000","11.76421","570.48737","485.29480","0.01870"
"138.80000","11.79760","571.90222","486.49838","0.01876"
"139.20000","11.83087","573.27582","487.66684","0.01881"
"139.60000","11.86420","574.43823","488.65567","0.01886"
"140.00000","11.89754","575.73145","489.75577","0.01891"
"140.40000","11.93088","576.90466","490.75378","0.01897"
"140.80000","11.96424","578.36139","491.99298","0.01902"
"141.20000","11.99752","579.13623","492.65210","0.01907"
"141.60000","12.03091","580.39960","493.72681","0.01913"
"142.00000","12.06416","581.85175","494.96210","0.01918"
"142.40000","12.09757","583.35303","496.23920","0.01923"
"142.80000","12.13083","584.28113","497.02869","0.01929"
"143.20000","12.16431","585.58734","498.13986","0.01934"
"143.60000","12.19749","586.74042","499.12073","0.01939"
"144.00000","12.23092","588.11896","500.29343","0.01944"
"144.40000","12.26425","589.23010","501.23862","0.01950"
"144.80000","12.29750","590.59216","502.39728","0.01955"
"145.20000","12.33093","591.42542","503.10611","0.01960"
"145.60000","12.36422","592.90497","504.36472","0.01966"
"146.00000","12.39759","594.18787","505.45602","0.01971"
"146.40000","12.43089","595.34241","506.43817","0.01976"
"146.80000","12.46425","596.73975","507.62683","0.01982"
"147.20000","12.49751","597.85724","508.57745","0.01987"
"147.60000","12.53095","599.01953","509.56616","0.01992"
"148.00000","12.56420","600.40485","510.74460","0.01997"
"148.40000","12.59765","601.37042","511.56601","0.02003"
"148.80000","12.63085","602.58655","512.60052","0.02008"
"149.20000","12.66429","603.62946","513.48767","0.02013"
"149.60000","12.69754","604.98065","514.63708","0.02019"
"150.00000","12.73090","606.21967","515.69110","0.02024"
"150.40000","12.76428","607.44232","516.73114","0.02029"
"150.80000","12.79756","608.48596","517.61896","0.02035"
"151.20000","12.83096","610.06598","518.96301","0.02040"
"151.60000","12.86424","610.84595","519.62653","0.02045"
"152.00000","12.89761","612.30841","520.87061","0.02050"
"152.40000","12.93090","613.06940","521.51794","0.02056"
"152.80000","12.96428","614.46338","522.70374","0.02061"
"153.20000","12.99757","615.73322","523.78394","0.02066"
"153.60000","13.03095","617.05054","524.90454","0.02072"
"154.00000","13.06424","618.04138","525.74744","0.02077"
"154.40000","13.09756","619.06934","526.62189","0.02082"
"154.80000","13.13093","620.24396","527.62109","0.02088"
"155.20000","13.16422","621.38605","528.59265","0.02093"
"155.60000","13.19762","622.75690","529.75879","0.02098"
"156.00000","13.23090","623.79596","530.64264","0.02103"
"156.40000","13.26424","625.17688","531.81738","0.02109"
"156.80000","13.29751","626.37451","532.83612","0.02114"
"157.20000","13.33093","627.41516","533.72137","0.02119"
"157.60000","13.36421","628.55206","534.68854","0.02125"
"158.00000","13.39763","629.66687","535.63684","0.02130"
"158.40000","13.43087","630.64496","536.46887","0.02135"
"158.80000","13.46429","631.78387","537.43774","0.02140"
"159.20000","13.49752","633.06366","538.52637","0.02146"
"159.60000","13.53092","634.32257","539.59729","0.02151"
"160.00000","13.56421","635.14954","540.30078","0.02156"
"160.40000","13.59755","636.94818","541.83081","0.02162"
"160.80000","13.63096","637.66266","542.43860","0.02167"
"161.20000","13.66417","639.17773","543.72742","0.02172"
"161.60000","13.69760","639.87775","544.32294","0.02178"
"162.00000","13.73081","641.08521","545.35004","0.02183"
"162.40000","13.76426","642.36035","546.43475","0.02188"
"162.80000","13.79755","643.41809","547.33453","0.02193"
"163.20000","13.83091","644.57477","548.31848","0.02199"
"163.60000","13.86422","645.56134","549.15778","0.02204"
"164.00000","13.89751","647.03223","550.40900","0.02209"
"164.40000","13.93087","648.35437","551.53369","0.02215"
"164.80000","13.96422","648.76050","551.87915","0.02220"
"165.20000","13.99754","650.21259","553.11444","0.02225"
"165.60000","14.03093","651.30103","554.04034","0.02231"
"166.00000","14.06420","652.58710","555.13434","0.02236"
"166.40000","14.09754","653.49481","555.90649","0.02241"
"166.80000","14.13091","654.55902","556.81177","0.02246"
"167.20000","14.16417","655.85004","557.91003","0.02252"
"167.60000","14.19762","657.22028","559.07562","0.02257"
"168.00000","14.23088","658.29877","559.99304","0.02262"
"168.40000","14.26426","659.36511","560.90015","0.02268"
"168.80000","14.29753","660.38275","561.76587","0.02273"
"169.20000","14.33089","661.25525","562.50806","0.02278"
"169.60000","14.36423","662.23230","563.33917","0.02284"
"170.00000","14.39756","663.63092","564.52893","0.02289"
"170.40000","14.43094","664.60089","565.35406","0.02294"
"170.80000","14.46421","665.88794","566.44891","0.02299"
"171.20000","14.49760","667.06201","567.44769","0.02305"
"171.60000","14.53088","668.12567","568.35248","0.02310"
"172.00000","14.56427","668.89673","569.00842","0.02315"
"172.40000","14.59756","670.29431","570.19727","0.02321"
"172.80000","14.63102","671.17767","570.94873","0.02326"
"173.20000","14.66419","672.27667","571.88361","0.02331"
"173.60000","14.69762","673.44275","572.87555","0.02337"
"174.00000","14.73086","674.32605","573.62695","0.02342"
"174.40000","14.76427","675.32532","574.47699","0.02347"
"174.80000","14.79760","676.59985","575.56122","0.02352"
"175.20000","14.83094","677.72644","576.51953","0.02358"
"175.60000","14.86425","678.63690","577.29407","0.02363"
"176.00000","14.89757","679.41180","577.95325","0.02368"
"176.40000","14.93092","680.85962","579.18481","0.02374"
"176.80000","14.96424","682.12347","580.25995","0.02379"
"177.20000","14.99761","683.20801","581.18256","0.02384"
"177.60000","15.03090","683.95856","581.82098","0.02390"
"178.00000","15.06431","684.80963","582.54498","0.02395"
"178.40000","15.09753","685.98755","583.54700","0.02400"
"178.80000","15.13095","687.34198","584.69916","0.02405"
"179.20000","15.16418","688.05780","585.30811","0.02411"
"179.60000","15.19762","689.25500","586.32654","0.02416"
"180.00000","15.23092","690.20386","587.13367","0.02421"
"180.40000","15.26422","691.52081","588.25397","0.02427"
"180.80000","15.29761","692.40045","589.00226","0.02432"
"181.20000","15.33082","693.60236","590.02466","0.02437"
"181.60000","15.36427","694.27808","590.59949","0.02443"
"182.00000","15.39753","695.51050","591.64783","0.02448"
"182.40000","15.43091","696.47504","592.46838","0.02453"
"182.80000","15.46421","697.34283","593.20654","0.02458"
"183.20000","15.49762","698.68518","594.34845","0.02464"
"183.60000","15.53085","699.59058","595.11865","0.02469"
"184.00000","15.56423","700.63965","596.01105","0.02474"
"184.40000","15.59753","701.77850","596.97986","0.02480"
"184.80000","15.63091","702.91144","597.94360","0.02485"
"185.20000","15.66423","703.85388","598.74530","0.02490"
"185.60000","15.69754","704.58813","599.36987","0.02496"
"186.00000","15.73090","705.59454","600.22601","0.02501"
"186.40000","15.76414","706.46118","600.96326","0.02506"
"186.80000","15.79761","707.49603","601.84357","0.02511"
"187.20000","15.83083","708.54822","602.73859","0.02517"
"187.60000","15.86428","709.81335","603.81482","0.02522"
"188.00000","15.89750","710.61212","604.49432","0.02527"
"188.40000","15.93091","711.58954","605.32574","0.02533"
"188.80000","15.96416","712.69232","606.26385","0.02538"
"189.20000","15.99759","714.03632","607.40717","0.02543"
"189.60000","16.03089","714.42798","607.74036","0.02549"
"190.00000","16.06421","715.24756","608.43750","0.02554"
"190.40000","16.09760","716.50751","609.50934","0.02559"
"190.80000","16.13082","717.41638","610.28247","0.02564"
"191.20000","16.16425","718.71344","611.38580","0.02570"
"191.60000","16.19750","719.58575","612.12787","0.02575"
"192.00000","16.23094","720.62842","613.01483","0.02580"
"192.40000","16.26423","721.54413","613.79382","0.02586"
"192.80000","16.29759","722.38770","614.51141","0.02591"
"193.20000","16.33089","723.43512","615.40240","0.02596"
"193.60000","16.36422","724.31329","616.14941","0.02602"
"194.00000","16.39757","725.50818","617.16589","0.02607"
"194.40000","16.43089","726.53082","618.03583","0.02612"
"194.80000","16.46425","727.35864","618.74005","0.02617"
"195.20000","16.49762","728.09570","619.36700","0.02623"
"195.60000","16.53090","729.37787","620.45770","0.02628"
"196.00000","16.56421","730.45587","621.37476","0.02633"
"196.40000","16.59763","731.19373","622.00238","0.02639"
"196.80000","16.63086","732.19513","622.85425","0.02644"
"197.20000","16.66433","733.11908","623.64026","0.02649"
"197.60000","16.69752","733.77924","624.20178","0.02655"
"198.00000","16.73096","735.31403","625.50739","0.02660"
"198.40000","16.76419","736.01196","626.10114","0.02665"
"198.80000","16.79762","736.79871","626.77039","0.02670"
"199.20000","16.83093","737.65875","627.50201","0.02676"
"199.60000","16.86423","738.91339","628.56927","0.02681"
"200.00000","16.89762","739.90356","629.41156","0.02686"
"200.40000","16.93088","741.00824","630.35126","0.02692"
"200.80000","16.96426","741.79248","631.01843","0.02697"
"201.20000","16.99759","742.68958","631.78156","0.02702"
"201.60000","17.03089","743.75085","632.68433","0.02708"
"202.00000","17.06426","744.28290","633.13690","0.02713"
"202.40000","17.09761","745.41467","634.09967","0.02718"
"202.80000","17.13089","746.38251","634.92297","0.02723"
"203.20000","17.16425","747.66687","636.01556","0.02729"
"203.60000","17.19753","748.24475","636.50714","0.02734"
"204.00000","17.23091","748.90564","637.06934","0.02739"
"204.40000","17.26425","749.66840","637.71820","0.02745"
"204.80000","17.29757","750.85034","638.72363","0.02750"
"205.20000","17.33090","751.93262","639.64429","0.02755"
"205.60000","17.36417","752.68860","640.28735","0.02760"
"206.00000","17.39756","753.56506","641.03296","0.02766"
"206.40000","17.43088","754.69727","641.99609","0.02771"
"206.80000","17.46426","755.27930","642.49121","0.02776"
"207.20000","17.49755","756.31274","643.37030","0.02782"
"207.60000","17.53090","757.35260","644.25488","0.02787"
"208.00000","17.56418","758.19012","644.96735","0.02792"
"208.40000","17.59761","759.31256","645.92218","0.02798"
"208.80000","17.63081","760.31592","646.77570","0.02803"
"209.20000","17.66428","761.13428","647.47186","0.02808"
"209.60000","17.69755","761.95941","648.17377","0.02813"
"210.00000","17.73086","762.85272","648.93365","0.02819"
"210.40000","17.76423","764.01117","649.91913","0.02824"
"210.80000","17.79750","764.53351","650.36346","0.02829"
"211.20000","17.83090","765.60712","651.27673","0.02835"
"211.60000","17.86422","766.77887","652.27350","0.02840"
"212.00000","17.89758","767.58551","652.95972","0.02845"
"212.40000","17.93087","768.62634","653.84509","0.02851"
"212.80000","17.96423","769.23651","654.36414","0.02856"
"213.20000","17.99750","770.43005","655.37946","0.02861"
"213.60000","18.03093","771.25702","656.08295","0.02866"
"214.00000","18.06419","771.97284","656.69183","0.02872"
"214.40000","18.09764","772.87195","657.45667","0.02877"
"214.80000","18.13083","773.80890","658.25372","0.02882"
"215.20000","18.16427","774.90100","659.18274","0.02888"
"215.60000","18.19754","775.65363","659.82300","0.02893"
"216.00000","18.23090","776.75391","660.75897","0.02898"
"216.40000","18.26429","777.75922","661.61414","0.02904"
"216.80000","18.29753","778.58124","662.31342","0.02909"
"217.20000","18.33096","779.27136","662.90045","0.02914"
"217.60000","18.36419","780.17346","663.66785","0.02919"
"218.00000","18.39761","781.19043","664.53296","0.02925"
"218.40000","18.43089","781.73877","664.99939","0.02930"
"218.80000","18.46429","782.73651","665.84814","0.02935"
"219.20000","18.49759","783.41968","666.42932","0.02941"
"219.60000","18.53090","784.35010","667.22076","0.02946"
"220.00000","18.56427","785.19592","667.94031","0.02951"
"220.40000","18.59753","786.15863","668.75922","0.02957"
"220.80000","18.63096","786.89337","669.38428","0.02962"
"221.20000","18.66421","787.71234","670.08093","0.02967"
"221.60000","18.69765","788.78223","670.99103","0.02972"
"222.00000","18.73088","789.31165","671.44141","0.02978"
"222.40000","18.76430","790.26764","672.25464","0.02983"
"222.80000","18.79751","791.56372","673.35718","0.02988"
"223.20000","18.83097","791.95782","673.69244","0.02994"
"223.60000","18.86424","792.77679","674.38910","0.02999"
"224.00000","18.89764","793.67737","675.15515","0.03004"
"224.40000","18.93088","794.67047","676.00000","0.03010"
"224.80000","18.96429","795.37646","676.60052","0.03015"
"225.20000","18.99755","796.41223","677.48163","0.03020"
"225.60000","19.03090","797.12726","678.08990","0.03025"
"226.00000","19.06424","798.16003","678.96844","0.03031"
"226.40000","19.09756","798.91473","679.61041","0.03036"
"226.80000","19.13098","799.47479","680.08685","0.03041"
"227.20000","19.16417","800.49072","680.95105","0.03047"
"227.60000","19.19761","801.07007","681.44391","0.03052"
"228.00000","19.23083","801.86816","682.12280","0.03057"
"228.40000","19.26425","802.79529","682.91150","0.03063"
"228.80000","19.29758","803.35193","683.38501","0.03068"
"229.20000","19.33091","804.51318","684.37286","0.03073"
"229.60000","19.36423","805.13647","684.90308","0.03078"
"230.00000","19.39751","805.83514","685.49738","0.03084"
"230.40000","19.43090","806.93463","686.43268","0.03089"
"230.80000","19.46421","807.43451","686.85791","0.03094"
"231.20000","19.49757","808.40045","687.67963","0.03100"
"231.60000","19.53088","809.12195","688.29340","0.03105"
"232.00000","19.56422","810.20282","689.21283","0.03110"
"232.40000","19.59752","811.12262","689.99530","0.03116"
"232.80000","19.63091","811.91516","690.66949","0.03121"
"233.20000","19.66417","812.36304","691.05048","0.03126"
"233.60000","19.69760","813.07446","691.65564","0.03131"
"234.00000","19.73087","813.98511","692.43030","0.03137"
"234.40000","19.76424","814.96014","693.25970","0.03142"
"234.80000","19.79753","815.53717","693.75061","0.03147"
"235.20000","19.83084","816.46442","694.53937","0.03153"
"235.60000","19.86428","817.31421","695.26227","0.03158"
"236.00000","19.89750","818.41449","696.19824","0.03163"
"236.40000","19.93096","818.84540","696.56482","0.03169"
"236.80000","19.96420","819.64490","697.24487","0.03174"
"237.20000","19.99759","820.62744","698.08069","0.03179"
"237.60000","20.03085","821.15808","698.53210","0.03184"
"238.00000","20.06427","822.05969","699.29907","0.03190"
"238.40000","20.09753","822.80225","699.93073","0.03195"
"238.80000","20.13097","823.77863","700.76135","0.03200"
"239.20000","20.16423","824.16064","701.08630","0.03206"
"239.60000","20.19757","824.99780","701.79846","0.03211"
"240.00000","20.23090","825.63788","702.34296","0.03216"
"240.40000","20.26423","826.24713","702.86121","0.03222"
"240.80000","20.29761","827.42419","703.86249","0.03227"
"241.20000","20.33093","827.91229","704.27771","0.03232"
"241.60000","20.36426","829.02002","705.22003","0.03237"
"242.00000","20.39757","829.58685","705.70221","0.03243"
"242.40000","20.43091","830.41705","706.40839","0.03248"
"242.80000","20.46424","831.21887","707.09052","0.03253"
"243.20000","20.49759","832.03345","707.78345","0.03259"
"243.60000","20.53093","832.80042","708.43585","0.03264"
"244.00000","20.56430","833.60382","709.11926","0.03269"
"244.40000","20.59755","834.28918","709.70233","0.03275"
"244.80000","20.63094","835.25323","710.52240","0.03280"
"245.20000","20.66421","835.51025","710.74103","0.03285"
"245.60000","20.69757","836.72308","711.77277","0.03290"
"246.00000","20.73099","837.48694","712.42255","0.03296"
"246.40000","20.76421","838.05188","712.90314","0.03301"
"246.80000","20.79763","838.34637","713.15363","0.03306"
"247.20000","20.83087","839.09631","713.79156","0.03312"
"247.60000","20.86427","840.14288","714.68188","0.03317"
"248.00000","20.89754","840.64496","715.10895","0.03322"
"248.40000","20.93095","841.87115","716.15204","0.03328"
"248.80000","20.96422","842.21564","716.44507","0.03333"
"249.20000","20.99761","842.91278","717.03815","0.03338"
"249.60000","21.03089","843.36346","717.42151","0.03343"
"250.00000","21.06422","844.17151","718.10889","0.03349"
"250.40000","21.09754","845.03247","718.84125","0.03354"
"250.80000","21.13092","845.87231","719.55573","0.03359"
"251.20000","21.16426","846.41345","720.01605","0.03365"
"251.60000","21.19755","847.28815","720.76007","0.03370"
"252.00000","21.23091","847.61383","721.03717","0.03375"
"252.40000","21.26415","848.65833","721.92566","0.03380"
"252.80000","21.29759","849.16113","722.35339","0.03386"
"253.20000","21.33087","849.80225","722.89874","0.03391"
"253.60000","21.36425","850.93451","723.86194","0.03396"
"254.00000","21.39750","851.74335","724.54999","0.03402"
"254.40000","21.43092","852.21478","724.95105","0.03407"
"254.80000","21.46419","852.98083","725.60266","0.03412"
"255.20000","21.49755","853.57233","726.10583","0.03418"
"255.60000","21.53091","854.28131","726.70892","0.03423"
"256.00000","21.56419","854.63324","727.00830","0.03428"
"256.40000","21.59760","855.72052","727.93323","0.03434"
"256.80000","21.63081","856.29791","728.42444","0.03439"
"257.20000","21.66425","857.05481","729.06830","0.03444"
"257.60000","21.69749","857.43170","729.38892","0.03449"
"258.00000","21.73097","858.49622","730.29443","0.03455"
"258.40000","21.76420","859.00562","730.72778","0.03460"
"258.80000","21.79759","859.64539","731.27197","0.03465"
"259.20000","21.83090","860.28021","731.81201","0.03471"
"259.60000","21.86419","860.74579","732.20807","0.03476"
"260.00000","21.89758","861.53729","732.88135","0.03481"
"260.40000","21.93089","862.07281","733.33691","0.03486"
"260.80000","21.96425","862.84778","733.99615","0.03492"
"261.20000","21.99758","863.51056","734.56000","0.03497"
"261.60000","22.03091","864.10486","735.06549","0.03502"
"262.00000","22.06420","864.77081","735.63202","0.03508"
"262.40000","22.09761","865.42480","736.18835","0.03513"
"262.80000","22.13086","866.09875","736.76166","0.03518"
"263.20000","22.16433","866.97394","737.50616","0.03524"
"263.60000","22.19753","867.42621","737.89087","0.03529"
"264.00000","22.23096","868.20624","738.55444","0.03534"
"264.40000","22.26418","868.64124","738.92444","0.03539"
"264.80000","22.29759","869.42120","739.58795","0.03545"
"265.20000","22.33096","870.01959","740.09698","0.03550"
"265.60000","22.36422","870.72913","740.70056","0.03555"
"266.00000","22.39762","871.33423","741.21533","0.03561"
"266.40000","22.43089","871.74524","741.56494","0.03566"
"266.80000","22.46428","872.28900","742.02753","0.03571"
"267.20000","22.49756","873.03827","742.66486","0.03577"
"267.60000","22.53093","873.38013","742.95569","0.03582"
"268.00000","22.56425","873.97784","743.46417","0.03587"
"268.40000","22.59762","874.87555","744.22778","0.03592"
"268.80000","22.63089","875.29242","744.58240","0.03598"
"269.20000","22.66425","876.32910","745.46429","0.03603"
"269.60000","22.69756","876.55988","745.66058","0.03608"
"270.00000","22.73092","877.47803","746.44165","0.03614"
"270.40000","22.76428","878.08466","746.95770","0.03619"
"270.80000","22.79756","878.91400","747.66315","0.03624"
"271.20000","22.83092","879.36005","748.04260","0.03630"
"271.60000","22.86416","879.66321","748.30048","0.03635"
"271.84400","22.88456","1.07209","0.91199","0.03638"
"272.24400","22.91791","-0.61763","-0.52540","0.03643"
"272.64400","22.95128","-0.68988","-0.58685","0.03649"
"273.04400","22.98447","-0.21760","-0.18510","0.03654"
"273.44400","23.01795","-0.17035","-0.14491","0.03659"
"273.84400","23.05120","-0.65451","-0.55677","0.03665"
"274.24400","23.08457","-0.36948","-0.31430","0.03670"
"274.64400","23.11787","-0.32217","-0.27406","0.03675"
"275.04400","23.15125","-0.29912","-0.25445","0.03680"
"275.27500","23.17045","-0.11669","-0.09926","0.03684"