File: 4_13_2023_IsolatedSprings/J-Spring/Specimen_A/Specimen_RawData_3.csv
Time,Extension,Load
(s),(mm),(N)
"0.00000","0.15364","10.39458"
"0.10000","0.24303","14.76459"
"0.20000","0.24245","15.71614"
"0.30000","0.26788","19.23010"
"0.40000","0.29303","21.78156"
"0.50000","0.31819","24.22201"
"0.60000","0.34305","26.30895"
"0.70000","0.36830","28.64371"
"0.80000","0.39313","30.97720"
"0.90000","0.41818","33.23439"
"1.00000","0.44316","35.58726"
"1.10000","0.46807","37.95154"
"1.20000","0.49325","40.32511"
"1.30000","0.51808","42.66337"
"1.40000","0.54322","44.98741"
"1.50000","0.56813","47.32206"
"1.60000","0.59309","49.76218"
"1.70000","0.61823","52.13824"
"1.80000","0.64309","54.40682"
"1.90000","0.66825","56.82050"
"2.00000","0.69308","59.14805"
"2.10000","0.71816","61.53139"
"2.20000","0.74315","63.91234"
"2.30000","0.76811","66.21468"
"2.40000","0.79329","68.67075"
"2.50000","0.81809","71.02015"
"2.60000","0.84321","73.27595"
"2.70000","0.86812","75.63006"
"2.80000","0.89309","78.08157"
"2.90000","0.91822","80.38504"
"3.00000","0.94309","82.79279"
"3.10000","0.96824","85.07510"
"3.20000","0.99309","87.35684"
"3.30000","1.01815","89.84222"
"3.40000","1.04321","92.18147"
"3.50000","1.06808","94.42339"
"3.60000","1.09329","96.88714"
"3.70000","1.11807","99.17205"
"3.80000","1.14316","101.49461"
"3.90000","1.16814","103.82204"
"4.00000","1.19308","106.22639"
"4.10000","1.21828","108.44776"
"4.20000","1.24307","110.90436"
"4.30000","1.26825","113.22706"
"4.40000","1.29312","115.54479"
"4.50000","1.31812","117.85013"
"4.60000","1.34321","120.20398"
"4.70000","1.36805","122.35792"
"4.80000","1.39324","124.78808"
"4.90000","1.41809","127.03347"
"5.00000","1.44321","129.39360"
"5.10000","1.46815","131.72508"
"5.20000","1.49310","133.93745"
"5.30000","1.51828","136.21793"
"5.40000","1.54308","138.67484"
"5.50000","1.56821","141.05037"
"5.60000","1.59312","143.18446"
"5.70000","1.61810","145.53883"
"5.80000","1.64323","147.82048"
"5.90000","1.66805","150.08685"
"6.00000","1.69328","152.41826"
"6.10000","1.71806","154.63458"
"6.20000","1.74318","157.05038"
"6.30000","1.76819","159.31613"
"6.40000","1.79309","161.62805"
"6.50000","1.81827","163.82268"
"6.60000","1.84310","166.22899"
"6.70000","1.86817","168.51471"
"6.80000","1.89309","170.71245"
"6.90000","1.91807","173.07028"
"7.00000","1.94322","175.41646"
"7.10000","1.96808","177.58046"
"7.20000","1.99331","179.88644"
"7.30000","2.01811","182.14291"
"7.40000","2.04317","184.40121"
"7.50000","2.06822","186.75485"
"7.60000","2.09307","188.92824"
"7.70000","2.11826","191.18329"
"7.80000","2.14303","193.50258"
"7.90000","2.16820","195.83765"
"8.00000","2.19312","198.06071"
"8.10000","2.21810","200.31456"
"8.20000","2.24331","202.52744"
"8.30000","2.26806","204.78119"
"8.40000","2.29326","207.14830"
"8.50000","2.31809","209.29382"
"8.60000","2.34312","211.52597"
"8.70000","2.36821","213.79622"
"8.80000","2.39305","215.98381"
"8.90000","2.41828","218.30797"
"9.00000","2.44306","220.53790"
"9.10000","2.46824","222.76872"
"9.20000","2.49318","225.02219"
"9.30000","2.51810","227.27184"
"9.40000","2.54328","229.47791"
"9.50000","2.56807","231.75827"
"9.60000","2.59320","233.99554"
"9.70000","2.61808","236.26286"
"9.80000","2.64314","238.29996"
"9.90000","2.66819","240.72379"
"10.00000","2.69309","242.94632"
"10.10000","2.71826","245.15411"
"10.20000","2.74309","247.29749"
"10.30000","2.76818","249.59157"
"10.40000","2.79317","251.82599"
"10.50000","2.81810","253.98100"
"10.60000","2.84326","256.25491"
"10.70000","2.86807","258.44211"
"10.80000","2.89321","260.67068"
"10.90000","2.91812","262.85843"
"11.00000","2.94310","265.08597"
"11.10000","2.96826","267.30695"
"11.20000","2.99306","269.54056"
"11.30000","3.01826","271.81668"
"11.40000","3.04313","273.96109"
"11.50000","3.06814","276.01666"
"11.60000","3.09318","278.24704"
"11.70000","3.11807","280.67813"
"11.80000","3.14327","282.67868"
"11.90000","3.16805","284.96317"
"12.00000","3.19323","287.33325"
"12.10000","3.21815","289.30231"
"12.20000","3.24310","291.51138"
"12.30000","3.26826","293.79691"
"12.40000","3.29306","296.04333"
"12.50000","3.31824","298.14771"
"12.60000","3.34308","300.16455"
"12.70000","3.36815","302.53088"
"12.80000","3.39319","304.79337"
"12.90000","3.41806","306.99100"
"13.00000","3.44332","309.22134"
"13.10000","3.46806","311.27078"
"13.20000","3.49320","313.57925"
"13.30000","3.51813","315.74026"
"13.40000","3.54309","317.95709"
"13.50000","3.56825","320.16843"
"13.60000","3.59310","322.38440"
"13.70000","3.61825","324.56717"
"13.80000","3.64311","326.59140"
"13.90000","3.66817","328.94717"
"14.00000","3.69322","331.14114"
"14.10000","3.71809","333.29111"
"14.20000","3.74322","335.52084"
"14.30000","3.76809","337.70139"
"14.40000","3.79316","339.94662"
"14.50000","3.81815","342.08069"
"14.60000","3.84308","344.22504"
"14.70000","3.86826","346.48041"
"14.80000","3.89309","348.65701"
"14.90000","3.91821","350.89923"
"15.00000","3.94312","353.12250"
"15.10000","3.96812","355.22598"
"15.20000","3.99326","357.31354"
"15.30000","4.01806","359.60599"
"15.40000","4.04326","361.73889"
"15.50000","4.06811","363.89877"
"15.60000","4.09315","366.07217"
"15.70000","4.11818","368.32535"
"15.80000","4.14309","370.45596"
"15.90000","4.16830","372.58514"
"16.00000","4.19306","374.91028"
"16.10000","4.21821","377.15723"
"16.20000","4.24313","379.18585"
"16.30000","4.26806","381.39279"
"16.40000","4.29323","383.47910"
"16.50000","4.31807","385.79221"
"16.60000","4.34327","387.90881"
"16.70000","4.36809","390.07504"
"16.80000","4.39316","392.30396"
"16.90000","4.41821","394.41852"
"17.00000","4.44310","396.66202"
"17.10000","4.46827","398.85220"
"17.20000","4.49308","400.98917"
"17.30000","4.51820","403.15198"
"17.40000","4.54310","405.29434"
"17.50000","4.56810","407.49203"
"17.60000","4.59323","409.72601"
"17.70000","4.61809","411.81262"
"17.80000","4.64327","414.10727"
"17.90000","4.66811","416.28177"
"18.00000","4.69317","418.33981"
"18.10000","4.71823","420.55215"
"18.20000","4.74309","422.78244"
"18.30000","4.76825","424.88016"
"18.40000","4.79308","426.91501"
"18.50000","4.81816","429.16656"
"18.60000","4.84314","431.25073"
"18.70000","4.86809","433.44385"
"18.80000","4.89327","435.57138"
"18.90000","4.91808","437.77777"
"19.00000","4.94324","439.91675"
"19.10000","4.96813","441.98004"
"19.20000","4.99311","444.27560"
"19.30000","5.01823","446.37262"
"19.40000","5.04308","448.55792"
"19.50000","5.06825","450.70038"
"19.60000","5.09306","452.86621"
"19.70000","5.11812","454.99350"
"19.80000","5.14319","457.02341"
"19.90000","5.16808","459.20090"
"20.00000","5.19331","461.41739"
"20.10000","5.21806","463.50867"
"20.20000","5.24322","465.59592"
"20.30000","5.26815","467.77603"
"20.40000","5.29308","469.94510"
"20.50000","5.31824","472.04526"
"20.60000","5.34306","474.26270"
"20.70000","5.36828","476.48392"
"20.80000","5.39309","478.42859"
"20.90000","5.41816","480.68472"
"21.00000","5.44319","482.80185"
"21.10000","5.46810","484.84518"
"21.20000","5.49323","487.10083"
"21.30000","5.51806","489.14346"
"21.40000","5.54320","491.23517"
"21.50000","5.56814","493.45755"
"21.60000","5.59313","495.51678"
"21.70000","5.61828","497.71783"
"21.80000","5.64309","499.76410"
"21.90000","5.66823","501.87628"
"22.00000","5.69308","504.03867"
"22.10000","5.71814","506.09882"
"22.20000","5.74320","508.32751"
"22.30000","5.76807","510.30853"
"22.40000","5.79325","512.45764"
"22.50000","5.81809","514.60217"
"22.60000","5.84319","516.75970"
"22.70000","5.86816","518.78027"
"22.80000","5.89311","520.98285"
"22.90000","5.91827","523.01636"
"23.00000","5.94305","525.21356"
"23.10000","5.96820","527.43573"
"23.20000","5.99311","529.40253"
"23.30000","6.01812","531.54816"
"23.40000","6.04325","533.68433"
"23.50000","6.06808","535.57648"
"23.60000","6.09325","537.81085"
"23.70000","6.11809","539.83289"
"23.80000","6.14314","541.93500"
"23.90000","6.16818","544.01843"
"24.00000","6.19306","546.22809"
"24.10000","6.21823","548.25446"
"24.20000","6.24307","550.40167"
"24.30000","6.26824","552.49371"
"24.40000","6.29314","554.43341"
"24.50000","6.31813","556.70465"
"24.60000","6.34327","558.73187"
"24.70000","6.36806","560.83130"
"24.80000","6.39324","562.96771"
"24.90000","6.41808","565.03198"
"25.00000","6.44316","567.13654"
"25.10000","6.46817","569.17578"
"25.20000","6.49308","571.24005"
"25.30000","6.51827","573.48834"
"25.40000","6.54308","575.54565"
"25.50000","6.56823","577.58411"
"25.60000","6.59316","579.70911"
"25.70000","6.61813","581.60400"
"25.80000","6.64325","583.81616"
"25.90000","6.66808","585.92285"
"26.00000","6.69318","588.02136"
"26.10000","6.71808","589.97180"
"26.20000","6.74312","592.06433"
"26.30000","6.76818","594.07977"
"26.40000","6.79309","596.30042"
"26.50000","6.81829","598.25525"
"26.60000","6.84311","600.30865"
"26.70000","6.86820","602.55078"
"26.80000","6.89317","604.48364"
"26.90000","6.91808","606.49127"
"27.00000","6.94323","608.75037"
"27.10000","6.96803","610.67285"
"27.20000","6.99324","612.78741"
"27.30000","7.01810","614.65350"
"27.40000","7.04314","616.78870"
"27.50000","7.06825","618.91101"
"27.60000","7.09306","621.00140"
"27.70000","7.11826","623.09161"
"27.80000","7.14307","625.01373"
"27.90000","7.16817","627.15833"
"28.00000","7.19316","629.14758"
"28.10000","7.21808","631.15466"
"28.20000","7.24328","633.20374"
"28.30000","7.26807","635.29840"
"28.40000","7.29324","637.35724"
"28.50000","7.31815","639.38214"
"28.60000","7.34314","641.45203"
"28.70000","7.36827","643.49579"
"28.80000","7.39305","645.44720"
"28.90000","7.41826","647.58917"
"29.00000","7.44309","649.61023"
"29.10000","7.46816","651.66125"
"29.20000","7.49318","653.81531"
"29.30000","7.51810","655.73492"
"29.40000","7.54327","657.80786"
"29.50000","7.56806","659.81964"
"29.60000","7.59321","661.90997"
"29.70000","7.61813","663.87329"
"29.80000","7.64310","666.08246"
"29.90000","7.66824","667.97736"
"30.00000","7.69307","669.97131"
"30.10000","7.71826","671.88812"
"30.20000","7.74308","673.98041"
"30.30000","7.76812","676.05371"
"30.40000","7.79319","678.09619"
"30.50000","7.81807","680.11682"
"30.60000","7.84326","682.09259"
"30.70000","7.86812","684.14581"
"30.80000","7.89319","686.14252"
"30.90000","7.91814","688.22180"
"31.00000","7.94310","690.30530"
"31.10000","7.96823","692.12024"
"31.20000","7.99304","694.29889"
"31.30000","8.01826","696.45349"
"31.40000","8.04312","698.30756"
"31.50000","8.06815","700.42371"
"31.60000","8.09324","702.32043"
"31.70000","8.11807","704.38599"
"31.80000","8.14323","706.44177"
"31.90000","8.16807","708.37628"
"32.00000","8.19319","710.54388"
"32.10000","8.21815","712.47601"
"32.20000","8.24309","714.52728"
"32.30000","8.26832","716.61261"
"32.40000","8.29305","718.52100"
"32.50000","8.31822","720.68561"
"32.60000","8.34310","722.65564"
"32.70000","8.36811","724.73517"
"32.80000","8.39321","726.62231"
"32.90000","8.41809","728.61230"
"33.00000","8.44328","730.74237"
"33.10000","8.46810","732.65521"
"33.20000","8.49320","734.88074"
"33.30000","8.51818","736.60931"
"33.40000","8.54310","738.76343"
"33.50000","8.56825","740.72009"
"33.60000","8.59305","742.72784"
"33.70000","8.61818","744.88269"
"33.80000","8.64312","746.81958"
"33.90000","8.66811","748.82849"
"34.00000","8.69322","750.78815"
"34.10000","8.71810","752.71039"
"34.20000","8.74324","754.75757"
"34.30000","8.76810","756.77045"
"34.40000","8.79314","758.83234"
"34.50000","8.81820","760.68994"
"34.60000","8.84308","762.76337"
"34.70000","8.86825","764.78748"
"34.80000","8.89310","766.70941"
"34.90000","8.91820","768.75116"
"35.00000","8.94315","770.60706"
"35.10000","8.96813","772.78259"
"35.20000","8.99328","774.70795"
"35.30000","9.01805","776.59619"
"35.40000","9.04321","778.69421"
"35.50000","9.06810","780.60754"
"35.60000","9.09311","782.60089"
"35.70000","9.11821","784.71442"
"35.80000","9.14306","786.48877"
"35.90000","9.16825","788.54810"
"36.00000","9.19308","790.55933"
"36.10000","9.21820","792.60376"
"36.20000","9.24319","794.46344"
"36.30000","9.26813","796.58826"
"36.40000","9.29325","798.49988"
"36.50000","9.31808","800.49567"
"36.60000","9.34322","802.51471"
"36.70000","9.36811","804.37146"
"36.80000","9.39312","806.44934"
"36.90000","9.41820","808.48096"
"37.00000","9.44306","810.34174"
"37.10000","9.46829","812.42200"
"37.20000","9.49310","814.38171"
"37.30000","9.51820","816.38776"
"37.40000","9.54320","818.30994"
"37.50000","9.56808","820.21429"
"37.60000","9.59323","822.28510"
"37.70000","9.61807","824.24805"
"37.80000","9.64320","826.33057"
"37.90000","9.66812","828.10895"
"38.00000","9.69312","830.24420"
"38.10000","9.71825","832.09778"
"38.20000","9.74305","834.02142"
"38.30000","9.76825","836.13812"
"38.40000","9.79311","838.10046"
"38.50000","9.81814","840.13788"
"38.60000","9.84319","841.89557"
"38.70000","9.86808","843.95129"
"38.80000","9.89324","846.04834"
"38.90000","9.91806","847.97198"
"39.00000","9.94319","849.93231"
"39.10000","9.96816","851.83502"
"39.20000","9.99312","853.87396"
"39.30000","10.01828","855.85022"
"39.40000","10.04307","857.65424"
"39.50000","10.06824","859.77039"
"39.60000","10.09313","861.64697"
"39.70000","10.11813","863.61292"
"39.80000","10.14320","865.57361"
"39.90000","10.16806","867.50409"
"40.00000","10.19328","869.60968"
"40.10000","10.21809","871.42017"
"40.20000","10.24318","873.48792"
"40.30000","10.26816","875.39709"
"40.40000","10.29308","877.37256"
"40.50000","10.31823","879.29126"
"40.60000","10.34305","881.23474"
"40.70000","10.36821","883.24359"
"40.80000","10.39310","885.12897"
"40.90000","10.41816","887.10181"
"41.00000","10.44324","889.01886"
"41.10000","10.46809","890.96063"
"41.20000","10.49325","892.91772"
"41.30000","10.51808","895.00024"
"41.40000","10.54319","896.83478"
"41.50000","10.56816","898.85657"
"41.60000","10.59307","900.78333"
"41.70000","10.61824","902.59851"
"41.80000","10.64307","904.54578"
"41.90000","10.66822","906.58179"
"42.00000","10.69312","908.49866"
"42.10000","10.71814","910.43396"
"42.20000","10.74323","912.31091"
"42.30000","10.76807","914.24908"
"42.40000","10.79324","916.29315"
"42.50000","10.81810","918.13831"
"42.60000","10.84316","920.08917"
"42.70000","10.86818","922.08301"
"42.80000","10.89307","923.99304"
"42.90000","10.91828","925.94202"
"43.00000","10.94311","927.81305"
"43.10000","10.96819","929.83105"
"43.20000","10.99315","931.72852"
"43.30000","11.01809","933.70685"
"43.40000","11.04323","935.73993"
"43.50000","11.06805","937.56262"
"43.60000","11.09328","939.51562"
"43.70000","11.11811","941.35620"
"43.80000","11.14316","943.35693"
"43.90000","11.16822","945.28143"
"44.00000","11.19308","947.19733"
"44.10000","11.21828","949.13580"
"44.20000","11.24307","951.06720"
"44.30000","11.26818","953.07996"
"44.40000","11.29314","954.97986"
"44.50000","11.31810","956.91394"
"44.60000","11.34326","958.79120"
"44.70000","11.36806","960.74731"
"44.80000","11.39327","962.75342"
"44.90000","11.41812","964.61780"
"45.00000","11.44317","966.59784"
"45.10000","11.46822","968.52563"
"45.20000","11.49307","970.46063"
"45.30000","11.51822","972.45032"
"45.40000","11.54304","974.31995"
"45.50000","11.56816","976.38879"
"45.60000","11.59314","978.17731"
"45.70000","11.61814","980.28107"
"45.80000","11.64329","982.22845"
"45.90000","11.66811","984.06061"
"46.00000","11.69323","986.04858"
"46.10000","11.71811","987.91541"
"46.20000","11.74311","989.88776"
"46.30000","11.76817","991.74908"
"46.40000","11.79306","993.80396"
"46.50000","11.81827","995.58405"
"46.60000","11.84308","997.64038"
"46.70000","11.86817","999.56738"
"46.80000","11.89322","1001.46594"
"46.90000","11.91808","1003.43463"
"47.00000","11.94327","1005.39954"
"47.10000","11.96806","1007.31964"
"47.20000","11.99319","1009.22949"
"47.30000","12.01817","1011.17499"
"47.40000","12.04310","1013.16345"
"47.50000","12.06825","1015.14410"
"47.60000","12.09306","1016.85571"
"47.70000","12.11827","1019.08624"
"47.80000","12.14310","1020.78198"
"47.90000","12.16816","1022.76514"
"48.00000","12.19322","1024.69287"
"48.10000","12.21805","1026.60083"
"48.20000","12.24327","1028.66040"
"48.30000","12.26805","1030.48352"
"48.40000","12.29321","1032.64111"
"48.50000","12.31813","1034.46326"
"48.60000","12.34313","1036.37036"
"48.70000","12.36826","1038.32690"
"48.80000","12.39306","1040.21667"
"48.90000","12.41824","1042.22913"
"49.00000","12.44309","1044.24536"
"49.10000","12.46815","1046.24744"
"49.20000","12.49319","1048.04602"
"49.30000","12.51805","1050.01587"
"49.40000","12.54325","1051.97144"
"49.50000","12.56806","1053.90161"
"49.60000","12.59319","1055.79614"
"49.70000","12.61817","1057.67407"
"49.80000","12.64310","1059.54944"
"49.90000","12.66827","1061.65625"
"50.00000","12.69311","1063.44653"
"50.10000","12.71822","1065.39185"
"50.20000","12.74312","1067.34094"
"50.30000","12.76811","1069.40369"
"50.40000","12.79320","1071.13733"
"50.50000","12.81807","1073.19849"
"50.60000","12.84327","1074.96240"
"50.70000","12.86810","1077.08655"
"50.80000","12.89318","1078.99023"
"50.90000","12.91821","1080.90857"
"51.00000","12.94307","1082.80383"
"51.10000","12.96823","1084.78760"
"51.20000","12.99306","1086.62573"
"51.30000","13.01822","1088.74402"
"51.40000","13.04315","1090.48608"
"51.50000","13.06813","1092.39233"
"51.60000","13.09326","1094.36609"
"51.70000","13.11803","1096.27332"
"51.80000","13.14323","1098.25818"
"51.90000","13.16806","1100.15466"
"52.00000","13.19313","1102.09045"
"52.10000","13.21821","1103.97632"
"52.20000","13.24308","1105.83557"
"52.30000","13.26832","1107.84192"
"52.40000","13.29307","1109.71558"
"52.50000","13.31826","1111.69080"
"52.60000","13.34314","1113.53564"
"52.70000","13.36811","1115.34583"
"52.80000","13.39320","1117.30603"
"52.90000","13.41805","1119.18994"
"53.00000","13.44323","1121.19385"
"53.10000","13.46808","1123.13403"
"53.20000","13.49318","1124.99207"
"53.30000","13.51817","1126.85339"
"53.40000","13.54310","1128.84534"
"53.50000","13.56825","1130.79517"
"53.60000","13.59306","1132.78015"
"53.70000","13.61820","1134.68652"
"53.80000","13.64314","1136.55383"
"53.90000","13.66811","1138.39294"
"54.00000","13.69323","1140.33740"
"54.10000","13.71810","1142.33154"
"54.20000","13.74324","1144.19702"
"54.30000","13.76813","1146.13281"
"54.40000","13.79316","1148.03027"
"54.50000","13.81821","1149.93237"
"54.60000","13.84305","1151.82959"
"54.70000","13.86826","1153.74829"
"54.80000","13.89310","1155.71204"
"54.90000","13.91816","1157.57788"
"55.00000","13.94318","1159.48010"
"55.10000","13.96805","1161.29431"
"55.20000","13.99323","1163.32178"
"55.30000","14.01808","1165.07361"
"55.40000","14.04322","1167.15454"
"55.50000","14.06815","1168.85266"
"55.60000","14.09313","1170.98413"
"55.70000","14.11824","1172.79712"
"55.80000","14.14307","1174.64722"
"55.90000","14.16824","1176.72778"
"56.00000","14.19307","1178.52722"
"56.10000","14.21816","1180.34912"
"56.20000","14.24317","1182.35645"
"56.30000","14.26808","1184.17639"
"56.40000","14.29332","1186.18542"
"56.50000","14.31810","1188.11292"
"56.60000","14.34323","1190.06482"
"56.70000","14.36815","1191.94910"
"56.80000","14.39309","1193.86060"
"56.90000","14.41821","1195.90051"
"57.00000","14.44306","1197.66528"
"57.10000","14.46825","1199.74609"
"57.20000","14.49310","1201.54895"
"57.30000","14.51819","1203.47607"
"57.40000","14.54322","1205.51440"
"57.50000","14.56808","1207.33313"
"57.60000","14.59327","1209.43213"
"57.70000","14.61809","1211.28613"
"57.80000","14.64318","1213.29517"
"57.90000","14.66814","1215.29541"
"58.00000","14.69312","1217.12793"
"58.10000","14.71823","1219.14246"
"58.20000","14.74306","1221.02246"
"58.30000","14.76823","1223.03931"
"58.40000","14.79312","1224.87341"
"58.50000","14.81815","1226.86304"
"58.60000","14.84322","1228.60974"
"58.70000","14.86808","1230.72339"
"58.80000","14.89324","1232.61340"
"58.90000","14.91809","1234.56665"
"59.00000","14.94318","1236.59021"
"59.10000","14.96816","1238.32385"
"59.20000","14.99307","1240.48755"
"59.30000","15.01828","1242.32288"
"59.40000","15.04306","1244.32898"
"59.50000","15.06822","1246.27930"
"59.60000","15.09313","1248.18420"
"59.70000","15.11811","1250.01123"
"59.80000","15.14321","1252.05652"
"59.90000","15.16807","1253.98865"
"60.00000","15.19324","1255.85474"
"60.10000","15.21810","1257.84253"
"60.20000","15.24318","1259.82288"
"60.30000","15.26820","1261.67175"
"60.40000","15.29310","1263.59937"
"60.50000","15.31828","1265.61182"
"60.60000","15.34307","1267.38513"
"60.70000","15.36820","1269.39307"
"60.80000","15.39314","1271.19604"
"60.90000","15.41811","1273.10510"
"61.00000","15.44320","1275.07593"
"61.10000","15.46806","1276.98792"
"61.20000","15.49328","1278.89392"
"61.30000","15.51806","1280.77698"
"61.40000","15.54316","1282.71448"
"61.50000","15.56821","1284.81140"
"61.60000","15.59307","1286.57288"
"61.70000","15.61826","1288.58337"
"61.80000","15.64307","1290.44702"
"61.90000","15.66821","1292.25769"
"62.00000","15.69315","1294.08081"
"62.10000","15.71810","1296.10876"
"62.20000","15.74327","1298.07568"
"62.30000","15.76808","1299.79236"
"62.40000","15.79321","1301.85437"
"62.50000","15.81811","1303.79016"
"62.60000","15.84313","1305.70154"
"62.70000","15.86819","1307.63269"
"62.80000","15.89309","1309.53650"
"62.90000","15.91828","1311.54260"
"63.00000","15.94310","1313.33521"
"63.10000","15.96821","1315.30273"
"63.20000","15.99318","1317.29102"
"63.30000","16.01809","1319.16565"
"63.40000","16.04325","1321.10706"
"63.50000","16.06805","1322.99463"
"63.60000","16.09322","1325.04395"
"63.70000","16.11811","1326.76843"
"63.80000","16.14314","1328.82117"
"63.90000","16.16822","1330.73669"
"64.00000","16.19309","1332.55310"
"64.10000","16.21828","1334.62646"
"64.20000","16.24309","1336.48560"
"64.30000","16.26820","1338.36255"
"64.40000","16.29319","1340.34460"
"64.50000","16.31806","1342.20239"
"64.60000","16.34324","1344.22205"
"64.70000","16.36804","1346.02893"
"64.80000","16.39321","1348.05042"
"64.90000","16.41813","1349.95203"
"65.00000","16.44317","1351.89673"
"65.10000","16.46826","1353.63757"
"65.20000","16.49308","1355.65234"
"65.30000","16.51827","1357.63806"
"65.40000","16.54306","1359.41614"
"65.50000","16.56815","1361.37781"
"65.60000","16.59316","1363.19812"
"65.70000","16.61807","1365.22461"
"65.80000","16.64326","1367.23401"
"65.90000","16.66808","1369.03064"
"66.00000","16.69325","1370.94312"
"66.10000","16.71816","1372.78979"
"66.20000","16.74311","1374.66516"
"66.30000","16.76823","1376.66956"
"66.40000","16.79306","1378.62939"
"66.50000","16.81820","1380.51050"
"66.60000","16.84315","1382.48108"
"66.70000","16.86812","1384.47839"
"66.80000","16.89322","1386.28101"
"66.90000","16.91806","1388.10388"
"67.00000","16.94328","1390.16455"
"67.10000","16.96809","1391.99658"
"67.20000","16.99321","1393.90051"
"67.30000","17.01818","1395.82349"
"67.40000","17.04306","1397.79773"
"67.50000","17.06823","1399.78796"
"67.51200","17.07121","1400.01135"